Бот запущен!

Получен сигнал завершения. Завершаем работу бота...
Бот завершил работу. Программа завершена.
Бот завершил работу.
Бот запущен!

Получен сигнал завершения. Завершаем работу бота...
Бот завершил работу. Программа завершена.
Бот завершил работу.
Бот запущен!

Получен сигнал завершения. Завершаем работу бота...
Бот завершил работу. Программа завершена.
Бот завершил работу.
Бот запущен!

Получен сигнал завершения. Завершаем работу бота...
Бот завершил работу. Программа завершена.
Бот завершил работу.
Бот запущен!

Получен сигнал завершения. Завершаем работу бота...
Бот завершил работу. Программа завершена.
Бот завершил работу.
Бот запущен!

Получен сигнал завершения. Завершаем работу бота...
Бот завершил работу. Программа завершена.
Бот завершил работу.
Бот запущен!

Получен сигнал завершения. Завершаем работу бота...
Бот завершил работу. Программа завершена.
Бот завершил работу.
Бот запущен!

Получен сигнал завершения. Завершаем работу бота...
Бот завершил работу. Программа завершена.
Бот завершил работу.
2025-01-23 16:59:28,989 (__init__.py:1115 MainThread) ERROR - TeleBot: "Infinity polling exception: ('Connection aborted.', RemoteDisconnected('Remote end closed connection without response'))"
2025-01-23 16:59:28,990 (__init__.py:1117 MainThread) ERROR - TeleBot: "Exception traceback:
Traceback (most recent call last):
  File "/usr/lib/python3/dist-packages/urllib3/connectionpool.py", line 700, in urlopen
    httplib_response = self._make_request(
  File "/usr/lib/python3/dist-packages/urllib3/connectionpool.py", line 446, in _make_request
    six.raise_from(e, None)
  File "<string>", line 3, in raise_from
  File "/usr/lib/python3/dist-packages/urllib3/connectionpool.py", line 441, in _make_request
    httplib_response = conn.getresponse()
  File "/usr/lib/python3.10/http/client.py", line 1375, in getresponse
    response.begin()
  File "/usr/lib/python3.10/http/client.py", line 318, in begin
    version, status, reason = self._read_status()
  File "/usr/lib/python3.10/http/client.py", line 287, in _read_status
    raise RemoteDisconnected("Remote end closed connection without"
http.client.RemoteDisconnected: Remote end closed connection without response

During handling of the above exception, another exception occurred:

Traceback (most recent call last):
  File "/usr/lib/python3/dist-packages/requests/adapters.py", line 439, in send
    resp = conn.urlopen(
  File "/usr/lib/python3/dist-packages/urllib3/connectionpool.py", line 756, in urlopen
    retries = retries.increment(
  File "/usr/lib/python3/dist-packages/urllib3/util/retry.py", line 534, in increment
    raise six.reraise(type(error), error, _stacktrace)
  File "/usr/lib/python3/dist-packages/six.py", line 718, in reraise
    raise value.with_traceback(tb)
  File "/usr/lib/python3/dist-packages/urllib3/connectionpool.py", line 700, in urlopen
    httplib_response = self._make_request(
  File "/usr/lib/python3/dist-packages/urllib3/connectionpool.py", line 446, in _make_request
    six.raise_from(e, None)
  File "<string>", line 3, in raise_from
  File "/usr/lib/python3/dist-packages/urllib3/connectionpool.py", line 441, in _make_request
    httplib_response = conn.getresponse()
  File "/usr/lib/python3.10/http/client.py", line 1375, in getresponse
    response.begin()
  File "/usr/lib/python3.10/http/client.py", line 318, in begin
    version, status, reason = self._read_status()
  File "/usr/lib/python3.10/http/client.py", line 287, in _read_status
    raise RemoteDisconnected("Remote end closed connection without"
urllib3.exceptions.ProtocolError: ('Connection aborted.', RemoteDisconnected('Remote end closed connection without response'))

During handling of the above exception, another exception occurred:

Traceback (most recent call last):
  File "/usr/local/lib/python3.10/dist-packages/telebot/__init__.py", line 1110, in infinity_polling
    self.polling(non_stop=True, timeout=timeout, long_polling_timeout=long_polling_timeout,
  File "/usr/local/lib/python3.10/dist-packages/telebot/__init__.py", line 1198, in polling
    self.__threaded_polling(non_stop=non_stop, interval=interval, timeout=timeout, long_polling_timeout=long_polling_timeout,
  File "/usr/local/lib/python3.10/dist-packages/telebot/__init__.py", line 1273, in __threaded_polling
    raise e
  File "/usr/local/lib/python3.10/dist-packages/telebot/__init__.py", line 1234, in __threaded_polling
    polling_thread.raise_exceptions()
  File "/usr/local/lib/python3.10/dist-packages/telebot/util.py", line 111, in raise_exceptions
    raise self.exception_info
  File "/usr/local/lib/python3.10/dist-packages/telebot/util.py", line 93, in run
    task(*args, **kwargs)
  File "/usr/local/lib/python3.10/dist-packages/telebot/__init__.py", line 688, in __retrieve_updates
    updates = self.get_updates(offset=(self.last_update_id + 1),
  File "/usr/local/lib/python3.10/dist-packages/telebot/__init__.py", line 660, in get_updates
    json_updates = apihelper.get_updates(
  File "/usr/local/lib/python3.10/dist-packages/telebot/apihelper.py", line 332, in get_updates
    return _make_request(token, method_url, params=payload)
  File "/usr/local/lib/python3.10/dist-packages/telebot/apihelper.py", line 162, in _make_request
    result = _get_req_session().request(
  File "/usr/lib/python3/dist-packages/requests/sessions.py", line 544, in request
    resp = self.send(prep, **send_kwargs)
  File "/usr/lib/python3/dist-packages/requests/sessions.py", line 657, in send
    r = adapter.send(request, **kwargs)
  File "/usr/lib/python3/dist-packages/requests/adapters.py", line 498, in send
    raise ConnectionError(err, request=request)
requests.exceptions.ConnectionError: ('Connection aborted.', RemoteDisconnected('Remote end closed connection without response'))
"
Бот запущен!

Получен сигнал завершения. Завершаем работу бота...
Бот завершил работу. Программа завершена.
Бот завершил работу.
2025-01-27 12:40:53,696 (__init__.py:1115 MainThread) ERROR - TeleBot: "Infinity polling exception: 5280216819"
2025-01-27 12:40:53,696 (__init__.py:1117 MainThread) ERROR - TeleBot: "Exception traceback:
Traceback (most recent call last):
  File "/usr/local/lib/python3.10/dist-packages/telebot/__init__.py", line 1110, in infinity_polling
    self.polling(non_stop=True, timeout=timeout, long_polling_timeout=long_polling_timeout,
  File "/usr/local/lib/python3.10/dist-packages/telebot/__init__.py", line 1198, in polling
    self.__threaded_polling(non_stop=non_stop, interval=interval, timeout=timeout, long_polling_timeout=long_polling_timeout,
  File "/usr/local/lib/python3.10/dist-packages/telebot/__init__.py", line 1273, in __threaded_polling
    raise e
  File "/usr/local/lib/python3.10/dist-packages/telebot/__init__.py", line 1235, in __threaded_polling
    self.worker_pool.raise_exceptions()
  File "/usr/local/lib/python3.10/dist-packages/telebot/util.py", line 150, in raise_exceptions
    raise self.exception_info
  File "/usr/local/lib/python3.10/dist-packages/telebot/util.py", line 93, in run
    task(*args, **kwargs)
  File "/usr/local/lib/python3.10/dist-packages/telebot/__init__.py", line 9233, in _run_middlewares_and_handler
    result = handler['function'](message)
  File "/root/TelegramBot/body.py", line 32, in handle_answers
    process_answer(bot, message)
  File "/root/TelegramBot/functions.py", line 202, in process_answer
    del user_question_state[user_id]
KeyError: 5280216819
"
2025-01-28 06:11:12,054 (__init__.py:1115 MainThread) ERROR - TeleBot: "Infinity polling exception: HTTPSConnectionPool(host='api.telegram.org', port=443): Read timed out. (read timeout=10)"
2025-01-28 06:11:12,055 (__init__.py:1117 MainThread) ERROR - TeleBot: "Exception traceback:
Traceback (most recent call last):
  File "/usr/lib/python3/dist-packages/urllib3/connectionpool.py", line 446, in _make_request
    six.raise_from(e, None)
  File "<string>", line 3, in raise_from
  File "/usr/lib/python3/dist-packages/urllib3/connectionpool.py", line 441, in _make_request
    httplib_response = conn.getresponse()
  File "/usr/lib/python3.10/http/client.py", line 1375, in getresponse
    response.begin()
  File "/usr/lib/python3.10/http/client.py", line 318, in begin
    version, status, reason = self._read_status()
  File "/usr/lib/python3.10/http/client.py", line 279, in _read_status
    line = str(self.fp.readline(_MAXLINE + 1), "iso-8859-1")
  File "/usr/lib/python3.10/socket.py", line 705, in readinto
    return self._sock.recv_into(b)
  File "/usr/lib/python3.10/ssl.py", line 1303, in recv_into
    return self.read(nbytes, buffer)
  File "/usr/lib/python3.10/ssl.py", line 1159, in read
    return self._sslobj.read(len, buffer)
TimeoutError: The read operation timed out

During handling of the above exception, another exception occurred:

Traceback (most recent call last):
  File "/usr/lib/python3/dist-packages/requests/adapters.py", line 439, in send
    resp = conn.urlopen(
  File "/usr/lib/python3/dist-packages/urllib3/connectionpool.py", line 756, in urlopen
    retries = retries.increment(
  File "/usr/lib/python3/dist-packages/urllib3/util/retry.py", line 534, in increment
    raise six.reraise(type(error), error, _stacktrace)
  File "/usr/lib/python3/dist-packages/six.py", line 719, in reraise
    raise value
  File "/usr/lib/python3/dist-packages/urllib3/connectionpool.py", line 700, in urlopen
    httplib_response = self._make_request(
  File "/usr/lib/python3/dist-packages/urllib3/connectionpool.py", line 448, in _make_request
    self._raise_timeout(err=e, url=url, timeout_value=read_timeout)
  File "/usr/lib/python3/dist-packages/urllib3/connectionpool.py", line 337, in _raise_timeout
    raise ReadTimeoutError(
urllib3.exceptions.ReadTimeoutError: HTTPSConnectionPool(host='api.telegram.org', port=443): Read timed out. (read timeout=10)

During handling of the above exception, another exception occurred:

Traceback (most recent call last):
  File "/usr/local/lib/python3.10/dist-packages/telebot/__init__.py", line 1110, in infinity_polling
    self.polling(non_stop=True, timeout=timeout, long_polling_timeout=long_polling_timeout,
  File "/usr/local/lib/python3.10/dist-packages/telebot/__init__.py", line 1198, in polling
    self.__threaded_polling(non_stop=non_stop, interval=interval, timeout=timeout, long_polling_timeout=long_polling_timeout,
  File "/usr/local/lib/python3.10/dist-packages/telebot/__init__.py", line 1273, in __threaded_polling
    raise e
  File "/usr/local/lib/python3.10/dist-packages/telebot/__init__.py", line 1234, in __threaded_polling
    polling_thread.raise_exceptions()
  File "/usr/local/lib/python3.10/dist-packages/telebot/util.py", line 111, in raise_exceptions
    raise self.exception_info
  File "/usr/local/lib/python3.10/dist-packages/telebot/util.py", line 93, in run
    task(*args, **kwargs)
  File "/usr/local/lib/python3.10/dist-packages/telebot/__init__.py", line 688, in __retrieve_updates
    updates = self.get_updates(offset=(self.last_update_id + 1),
  File "/usr/local/lib/python3.10/dist-packages/telebot/__init__.py", line 660, in get_updates
    json_updates = apihelper.get_updates(
  File "/usr/local/lib/python3.10/dist-packages/telebot/apihelper.py", line 332, in get_updates
    return _make_request(token, method_url, params=payload)
  File "/usr/local/lib/python3.10/dist-packages/telebot/apihelper.py", line 162, in _make_request
    result = _get_req_session().request(
  File "/usr/lib/python3/dist-packages/requests/sessions.py", line 544, in request
    resp = self.send(prep, **send_kwargs)
  File "/usr/lib/python3/dist-packages/requests/sessions.py", line 657, in send
    r = adapter.send(request, **kwargs)
  File "/usr/lib/python3/dist-packages/requests/adapters.py", line 529, in send
    raise ReadTimeout(e, request=request)
requests.exceptions.ReadTimeout: HTTPSConnectionPool(host='api.telegram.org', port=443): Read timed out. (read timeout=10)
"
2025-01-29 11:26:15,161 (__init__.py:1115 MainThread) ERROR - TeleBot: "Infinity polling exception: 1996893560"
2025-01-29 11:26:15,162 (__init__.py:1117 MainThread) ERROR - TeleBot: "Exception traceback:
Traceback (most recent call last):
  File "/usr/local/lib/python3.10/dist-packages/telebot/__init__.py", line 1110, in infinity_polling
    self.polling(non_stop=True, timeout=timeout, long_polling_timeout=long_polling_timeout,
  File "/usr/local/lib/python3.10/dist-packages/telebot/__init__.py", line 1198, in polling
    self.__threaded_polling(non_stop=non_stop, interval=interval, timeout=timeout, long_polling_timeout=long_polling_timeout,
  File "/usr/local/lib/python3.10/dist-packages/telebot/__init__.py", line 1273, in __threaded_polling
    raise e
  File "/usr/local/lib/python3.10/dist-packages/telebot/__init__.py", line 1235, in __threaded_polling
    self.worker_pool.raise_exceptions()
  File "/usr/local/lib/python3.10/dist-packages/telebot/util.py", line 150, in raise_exceptions
    raise self.exception_info
  File "/usr/local/lib/python3.10/dist-packages/telebot/util.py", line 93, in run
    task(*args, **kwargs)
  File "/usr/local/lib/python3.10/dist-packages/telebot/__init__.py", line 9233, in _run_middlewares_and_handler
    result = handler['function'](message)
  File "/root/TelegramBot/body.py", line 32, in handle_answers
    process_answer(bot, message)
  File "/root/TelegramBot/functions.py", line 202, in process_answer
    del user_question_state[user_id]
KeyError: 1996893560
"
2025-01-31 16:13:11,539 (__init__.py:1115 MainThread) ERROR - TeleBot: "Infinity polling exception: HTTPSConnectionPool(host='api.telegram.org', port=443): Read timed out. (read timeout=10)"
2025-01-31 16:13:11,541 (__init__.py:1117 MainThread) ERROR - TeleBot: "Exception traceback:
Traceback (most recent call last):
  File "/usr/lib/python3/dist-packages/urllib3/connectionpool.py", line 446, in _make_request
    six.raise_from(e, None)
  File "<string>", line 3, in raise_from
  File "/usr/lib/python3/dist-packages/urllib3/connectionpool.py", line 441, in _make_request
    httplib_response = conn.getresponse()
  File "/usr/lib/python3.10/http/client.py", line 1375, in getresponse
    response.begin()
  File "/usr/lib/python3.10/http/client.py", line 318, in begin
    version, status, reason = self._read_status()
  File "/usr/lib/python3.10/http/client.py", line 279, in _read_status
    line = str(self.fp.readline(_MAXLINE + 1), "iso-8859-1")
  File "/usr/lib/python3.10/socket.py", line 705, in readinto
    return self._sock.recv_into(b)
  File "/usr/lib/python3.10/ssl.py", line 1303, in recv_into
    return self.read(nbytes, buffer)
  File "/usr/lib/python3.10/ssl.py", line 1159, in read
    return self._sslobj.read(len, buffer)
TimeoutError: The read operation timed out

During handling of the above exception, another exception occurred:

Traceback (most recent call last):
  File "/usr/lib/python3/dist-packages/requests/adapters.py", line 439, in send
    resp = conn.urlopen(
  File "/usr/lib/python3/dist-packages/urllib3/connectionpool.py", line 756, in urlopen
    retries = retries.increment(
  File "/usr/lib/python3/dist-packages/urllib3/util/retry.py", line 534, in increment
    raise six.reraise(type(error), error, _stacktrace)
  File "/usr/lib/python3/dist-packages/six.py", line 719, in reraise
    raise value
  File "/usr/lib/python3/dist-packages/urllib3/connectionpool.py", line 700, in urlopen
    httplib_response = self._make_request(
  File "/usr/lib/python3/dist-packages/urllib3/connectionpool.py", line 448, in _make_request
    self._raise_timeout(err=e, url=url, timeout_value=read_timeout)
  File "/usr/lib/python3/dist-packages/urllib3/connectionpool.py", line 337, in _raise_timeout
    raise ReadTimeoutError(
urllib3.exceptions.ReadTimeoutError: HTTPSConnectionPool(host='api.telegram.org', port=443): Read timed out. (read timeout=10)

During handling of the above exception, another exception occurred:

Traceback (most recent call last):
  File "/usr/local/lib/python3.10/dist-packages/telebot/__init__.py", line 1110, in infinity_polling
    self.polling(non_stop=True, timeout=timeout, long_polling_timeout=long_polling_timeout,
  File "/usr/local/lib/python3.10/dist-packages/telebot/__init__.py", line 1198, in polling
    self.__threaded_polling(non_stop=non_stop, interval=interval, timeout=timeout, long_polling_timeout=long_polling_timeout,
  File "/usr/local/lib/python3.10/dist-packages/telebot/__init__.py", line 1273, in __threaded_polling
    raise e
  File "/usr/local/lib/python3.10/dist-packages/telebot/__init__.py", line 1234, in __threaded_polling
    polling_thread.raise_exceptions()
  File "/usr/local/lib/python3.10/dist-packages/telebot/util.py", line 111, in raise_exceptions
    raise self.exception_info
  File "/usr/local/lib/python3.10/dist-packages/telebot/util.py", line 93, in run
    task(*args, **kwargs)
  File "/usr/local/lib/python3.10/dist-packages/telebot/__init__.py", line 688, in __retrieve_updates
    updates = self.get_updates(offset=(self.last_update_id + 1),
  File "/usr/local/lib/python3.10/dist-packages/telebot/__init__.py", line 660, in get_updates
    json_updates = apihelper.get_updates(
  File "/usr/local/lib/python3.10/dist-packages/telebot/apihelper.py", line 332, in get_updates
    return _make_request(token, method_url, params=payload)
  File "/usr/local/lib/python3.10/dist-packages/telebot/apihelper.py", line 162, in _make_request
    result = _get_req_session().request(
  File "/usr/lib/python3/dist-packages/requests/sessions.py", line 544, in request
    resp = self.send(prep, **send_kwargs)
  File "/usr/lib/python3/dist-packages/requests/sessions.py", line 657, in send
    r = adapter.send(request, **kwargs)
  File "/usr/lib/python3/dist-packages/requests/adapters.py", line 529, in send
    raise ReadTimeout(e, request=request)
requests.exceptions.ReadTimeout: HTTPSConnectionPool(host='api.telegram.org', port=443): Read timed out. (read timeout=10)
"
2025-02-01 02:15:43,966 (__init__.py:1241 MainThread) ERROR - TeleBot: "Threaded polling exception: A request to the Telegram API was unsuccessful. Error code: 429. Description: Too Many Requests: retry after 5"
2025-02-01 02:15:43,967 (__init__.py:1243 MainThread) ERROR - TeleBot: "Exception traceback:
Traceback (most recent call last):
  File "/usr/local/lib/python3.10/dist-packages/telebot/__init__.py", line 1234, in __threaded_polling
    polling_thread.raise_exceptions()
  File "/usr/local/lib/python3.10/dist-packages/telebot/util.py", line 111, in raise_exceptions
    raise self.exception_info
  File "/usr/local/lib/python3.10/dist-packages/telebot/util.py", line 93, in run
    task(*args, **kwargs)
  File "/usr/local/lib/python3.10/dist-packages/telebot/__init__.py", line 688, in __retrieve_updates
    updates = self.get_updates(offset=(self.last_update_id + 1),
  File "/usr/local/lib/python3.10/dist-packages/telebot/__init__.py", line 660, in get_updates
    json_updates = apihelper.get_updates(
  File "/usr/local/lib/python3.10/dist-packages/telebot/apihelper.py", line 332, in get_updates
    return _make_request(token, method_url, params=payload)
  File "/usr/local/lib/python3.10/dist-packages/telebot/apihelper.py", line 168, in _make_request
    json_result = _check_result(method_name, result)
  File "/usr/local/lib/python3.10/dist-packages/telebot/apihelper.py", line 195, in _check_result
    raise ApiTelegramException(method_name, result, result_json)
telebot.apihelper.ApiTelegramException: A request to the Telegram API was unsuccessful. Error code: 429. Description: Too Many Requests: retry after 5
"
2025-02-01 02:15:44,317 (__init__.py:1241 MainThread) ERROR - TeleBot: "Threaded polling exception: A request to the Telegram API was unsuccessful. Error code: 429. Description: Too Many Requests: retry after 5"
2025-02-01 02:15:44,317 (__init__.py:1243 MainThread) ERROR - TeleBot: "Exception traceback:
Traceback (most recent call last):
  File "/usr/local/lib/python3.10/dist-packages/telebot/__init__.py", line 1234, in __threaded_polling
    polling_thread.raise_exceptions()
  File "/usr/local/lib/python3.10/dist-packages/telebot/util.py", line 111, in raise_exceptions
    raise self.exception_info
  File "/usr/local/lib/python3.10/dist-packages/telebot/util.py", line 93, in run
    task(*args, **kwargs)
  File "/usr/local/lib/python3.10/dist-packages/telebot/__init__.py", line 688, in __retrieve_updates
    updates = self.get_updates(offset=(self.last_update_id + 1),
  File "/usr/local/lib/python3.10/dist-packages/telebot/__init__.py", line 660, in get_updates
    json_updates = apihelper.get_updates(
  File "/usr/local/lib/python3.10/dist-packages/telebot/apihelper.py", line 332, in get_updates
    return _make_request(token, method_url, params=payload)
  File "/usr/local/lib/python3.10/dist-packages/telebot/apihelper.py", line 168, in _make_request
    json_result = _check_result(method_name, result)
  File "/usr/local/lib/python3.10/dist-packages/telebot/apihelper.py", line 195, in _check_result
    raise ApiTelegramException(method_name, result, result_json)
telebot.apihelper.ApiTelegramException: A request to the Telegram API was unsuccessful. Error code: 429. Description: Too Many Requests: retry after 5
"
2025-02-01 02:15:44,867 (__init__.py:1241 MainThread) ERROR - TeleBot: "Threaded polling exception: A request to the Telegram API was unsuccessful. Error code: 429. Description: Too Many Requests: retry after 5"
2025-02-01 02:15:44,867 (__init__.py:1243 MainThread) ERROR - TeleBot: "Exception traceback:
Traceback (most recent call last):
  File "/usr/local/lib/python3.10/dist-packages/telebot/__init__.py", line 1234, in __threaded_polling
    polling_thread.raise_exceptions()
  File "/usr/local/lib/python3.10/dist-packages/telebot/util.py", line 111, in raise_exceptions
    raise self.exception_info
  File "/usr/local/lib/python3.10/dist-packages/telebot/util.py", line 93, in run
    task(*args, **kwargs)
  File "/usr/local/lib/python3.10/dist-packages/telebot/__init__.py", line 688, in __retrieve_updates
    updates = self.get_updates(offset=(self.last_update_id + 1),
  File "/usr/local/lib/python3.10/dist-packages/telebot/__init__.py", line 660, in get_updates
    json_updates = apihelper.get_updates(
  File "/usr/local/lib/python3.10/dist-packages/telebot/apihelper.py", line 332, in get_updates
    return _make_request(token, method_url, params=payload)
  File "/usr/local/lib/python3.10/dist-packages/telebot/apihelper.py", line 168, in _make_request
    json_result = _check_result(method_name, result)
  File "/usr/local/lib/python3.10/dist-packages/telebot/apihelper.py", line 195, in _check_result
    raise ApiTelegramException(method_name, result, result_json)
telebot.apihelper.ApiTelegramException: A request to the Telegram API was unsuccessful. Error code: 429. Description: Too Many Requests: retry after 5
"
2025-02-01 02:15:50,741 (__init__.py:1241 MainThread) ERROR - TeleBot: "Threaded polling exception: A request to the Telegram API was unsuccessful. Error code: 502. Description: Bad Gateway"
2025-02-01 02:15:50,741 (__init__.py:1243 MainThread) ERROR - TeleBot: "Exception traceback:
Traceback (most recent call last):
  File "/usr/local/lib/python3.10/dist-packages/telebot/__init__.py", line 1234, in __threaded_polling
    polling_thread.raise_exceptions()
  File "/usr/local/lib/python3.10/dist-packages/telebot/util.py", line 111, in raise_exceptions
    raise self.exception_info
  File "/usr/local/lib/python3.10/dist-packages/telebot/util.py", line 93, in run
    task(*args, **kwargs)
  File "/usr/local/lib/python3.10/dist-packages/telebot/__init__.py", line 688, in __retrieve_updates
    updates = self.get_updates(offset=(self.last_update_id + 1),
  File "/usr/local/lib/python3.10/dist-packages/telebot/__init__.py", line 660, in get_updates
    json_updates = apihelper.get_updates(
  File "/usr/local/lib/python3.10/dist-packages/telebot/apihelper.py", line 332, in get_updates
    return _make_request(token, method_url, params=payload)
  File "/usr/local/lib/python3.10/dist-packages/telebot/apihelper.py", line 168, in _make_request
    json_result = _check_result(method_name, result)
  File "/usr/local/lib/python3.10/dist-packages/telebot/apihelper.py", line 195, in _check_result
    raise ApiTelegramException(method_name, result, result_json)
telebot.apihelper.ApiTelegramException: A request to the Telegram API was unsuccessful. Error code: 502. Description: Bad Gateway
"
2025-02-01 02:15:52,790 (__init__.py:1241 MainThread) ERROR - TeleBot: "Threaded polling exception: A request to the Telegram API was unsuccessful. Error code: 502. Description: Bad Gateway"
2025-02-01 02:15:52,790 (__init__.py:1243 MainThread) ERROR - TeleBot: "Exception traceback:
Traceback (most recent call last):
  File "/usr/local/lib/python3.10/dist-packages/telebot/__init__.py", line 1234, in __threaded_polling
    polling_thread.raise_exceptions()
  File "/usr/local/lib/python3.10/dist-packages/telebot/util.py", line 111, in raise_exceptions
    raise self.exception_info
  File "/usr/local/lib/python3.10/dist-packages/telebot/util.py", line 93, in run
    task(*args, **kwargs)
  File "/usr/local/lib/python3.10/dist-packages/telebot/__init__.py", line 688, in __retrieve_updates
    updates = self.get_updates(offset=(self.last_update_id + 1),
  File "/usr/local/lib/python3.10/dist-packages/telebot/__init__.py", line 660, in get_updates
    json_updates = apihelper.get_updates(
  File "/usr/local/lib/python3.10/dist-packages/telebot/apihelper.py", line 332, in get_updates
    return _make_request(token, method_url, params=payload)
  File "/usr/local/lib/python3.10/dist-packages/telebot/apihelper.py", line 168, in _make_request
    json_result = _check_result(method_name, result)
  File "/usr/local/lib/python3.10/dist-packages/telebot/apihelper.py", line 195, in _check_result
    raise ApiTelegramException(method_name, result, result_json)
telebot.apihelper.ApiTelegramException: A request to the Telegram API was unsuccessful. Error code: 502. Description: Bad Gateway
"
2025-02-01 02:16:06,809 (__init__.py:1115 MainThread) ERROR - TeleBot: "Infinity polling exception: HTTPSConnectionPool(host='api.telegram.org', port=443): Read timed out. (read timeout=10)"
2025-02-01 02:16:06,810 (__init__.py:1117 MainThread) ERROR - TeleBot: "Exception traceback:
Traceback (most recent call last):
  File "/usr/lib/python3/dist-packages/urllib3/connectionpool.py", line 446, in _make_request
    six.raise_from(e, None)
  File "<string>", line 3, in raise_from
  File "/usr/lib/python3/dist-packages/urllib3/connectionpool.py", line 441, in _make_request
    httplib_response = conn.getresponse()
  File "/usr/lib/python3.10/http/client.py", line 1375, in getresponse
    response.begin()
  File "/usr/lib/python3.10/http/client.py", line 318, in begin
    version, status, reason = self._read_status()
  File "/usr/lib/python3.10/http/client.py", line 279, in _read_status
    line = str(self.fp.readline(_MAXLINE + 1), "iso-8859-1")
  File "/usr/lib/python3.10/socket.py", line 705, in readinto
    return self._sock.recv_into(b)
  File "/usr/lib/python3.10/ssl.py", line 1303, in recv_into
    return self.read(nbytes, buffer)
  File "/usr/lib/python3.10/ssl.py", line 1159, in read
    return self._sslobj.read(len, buffer)
TimeoutError: The read operation timed out

During handling of the above exception, another exception occurred:

Traceback (most recent call last):
  File "/usr/lib/python3/dist-packages/requests/adapters.py", line 439, in send
    resp = conn.urlopen(
  File "/usr/lib/python3/dist-packages/urllib3/connectionpool.py", line 756, in urlopen
    retries = retries.increment(
  File "/usr/lib/python3/dist-packages/urllib3/util/retry.py", line 534, in increment
    raise six.reraise(type(error), error, _stacktrace)
  File "/usr/lib/python3/dist-packages/six.py", line 719, in reraise
    raise value
  File "/usr/lib/python3/dist-packages/urllib3/connectionpool.py", line 700, in urlopen
    httplib_response = self._make_request(
  File "/usr/lib/python3/dist-packages/urllib3/connectionpool.py", line 448, in _make_request
    self._raise_timeout(err=e, url=url, timeout_value=read_timeout)
  File "/usr/lib/python3/dist-packages/urllib3/connectionpool.py", line 337, in _raise_timeout
    raise ReadTimeoutError(
urllib3.exceptions.ReadTimeoutError: HTTPSConnectionPool(host='api.telegram.org', port=443): Read timed out. (read timeout=10)

During handling of the above exception, another exception occurred:

Traceback (most recent call last):
  File "/usr/local/lib/python3.10/dist-packages/telebot/__init__.py", line 1110, in infinity_polling
    self.polling(non_stop=True, timeout=timeout, long_polling_timeout=long_polling_timeout,
  File "/usr/local/lib/python3.10/dist-packages/telebot/__init__.py", line 1198, in polling
    self.__threaded_polling(non_stop=non_stop, interval=interval, timeout=timeout, long_polling_timeout=long_polling_timeout,
  File "/usr/local/lib/python3.10/dist-packages/telebot/__init__.py", line 1273, in __threaded_polling
    raise e
  File "/usr/local/lib/python3.10/dist-packages/telebot/__init__.py", line 1234, in __threaded_polling
    polling_thread.raise_exceptions()
  File "/usr/local/lib/python3.10/dist-packages/telebot/util.py", line 111, in raise_exceptions
    raise self.exception_info
  File "/usr/local/lib/python3.10/dist-packages/telebot/util.py", line 93, in run
    task(*args, **kwargs)
  File "/usr/local/lib/python3.10/dist-packages/telebot/__init__.py", line 688, in __retrieve_updates
    updates = self.get_updates(offset=(self.last_update_id + 1),
  File "/usr/local/lib/python3.10/dist-packages/telebot/__init__.py", line 660, in get_updates
    json_updates = apihelper.get_updates(
  File "/usr/local/lib/python3.10/dist-packages/telebot/apihelper.py", line 332, in get_updates
    return _make_request(token, method_url, params=payload)
  File "/usr/local/lib/python3.10/dist-packages/telebot/apihelper.py", line 162, in _make_request
    result = _get_req_session().request(
  File "/usr/lib/python3/dist-packages/requests/sessions.py", line 544, in request
    resp = self.send(prep, **send_kwargs)
  File "/usr/lib/python3/dist-packages/requests/sessions.py", line 657, in send
    r = adapter.send(request, **kwargs)
  File "/usr/lib/python3/dist-packages/requests/adapters.py", line 529, in send
    raise ReadTimeout(e, request=request)
requests.exceptions.ReadTimeout: HTTPSConnectionPool(host='api.telegram.org', port=443): Read timed out. (read timeout=10)
"
2025-02-03 04:13:04,624 (__init__.py:1115 MainThread) ERROR - TeleBot: "Infinity polling exception: HTTPSConnectionPool(host='api.telegram.org', port=443): Read timed out. (read timeout=10)"
2025-02-03 04:13:04,625 (__init__.py:1117 MainThread) ERROR - TeleBot: "Exception traceback:
Traceback (most recent call last):
  File "/usr/lib/python3/dist-packages/urllib3/connectionpool.py", line 446, in _make_request
    six.raise_from(e, None)
  File "<string>", line 3, in raise_from
  File "/usr/lib/python3/dist-packages/urllib3/connectionpool.py", line 441, in _make_request
    httplib_response = conn.getresponse()
  File "/usr/lib/python3.10/http/client.py", line 1375, in getresponse
    response.begin()
  File "/usr/lib/python3.10/http/client.py", line 318, in begin
    version, status, reason = self._read_status()
  File "/usr/lib/python3.10/http/client.py", line 279, in _read_status
    line = str(self.fp.readline(_MAXLINE + 1), "iso-8859-1")
  File "/usr/lib/python3.10/socket.py", line 705, in readinto
    return self._sock.recv_into(b)
  File "/usr/lib/python3.10/ssl.py", line 1303, in recv_into
    return self.read(nbytes, buffer)
  File "/usr/lib/python3.10/ssl.py", line 1159, in read
    return self._sslobj.read(len, buffer)
TimeoutError: The read operation timed out

During handling of the above exception, another exception occurred:

Traceback (most recent call last):
  File "/usr/lib/python3/dist-packages/requests/adapters.py", line 439, in send
    resp = conn.urlopen(
  File "/usr/lib/python3/dist-packages/urllib3/connectionpool.py", line 756, in urlopen
    retries = retries.increment(
  File "/usr/lib/python3/dist-packages/urllib3/util/retry.py", line 534, in increment
    raise six.reraise(type(error), error, _stacktrace)
  File "/usr/lib/python3/dist-packages/six.py", line 719, in reraise
    raise value
  File "/usr/lib/python3/dist-packages/urllib3/connectionpool.py", line 700, in urlopen
    httplib_response = self._make_request(
  File "/usr/lib/python3/dist-packages/urllib3/connectionpool.py", line 448, in _make_request
    self._raise_timeout(err=e, url=url, timeout_value=read_timeout)
  File "/usr/lib/python3/dist-packages/urllib3/connectionpool.py", line 337, in _raise_timeout
    raise ReadTimeoutError(
urllib3.exceptions.ReadTimeoutError: HTTPSConnectionPool(host='api.telegram.org', port=443): Read timed out. (read timeout=10)

During handling of the above exception, another exception occurred:

Traceback (most recent call last):
  File "/usr/local/lib/python3.10/dist-packages/telebot/__init__.py", line 1110, in infinity_polling
    self.polling(non_stop=True, timeout=timeout, long_polling_timeout=long_polling_timeout,
  File "/usr/local/lib/python3.10/dist-packages/telebot/__init__.py", line 1198, in polling
    self.__threaded_polling(non_stop=non_stop, interval=interval, timeout=timeout, long_polling_timeout=long_polling_timeout,
  File "/usr/local/lib/python3.10/dist-packages/telebot/__init__.py", line 1273, in __threaded_polling
    raise e
  File "/usr/local/lib/python3.10/dist-packages/telebot/__init__.py", line 1234, in __threaded_polling
    polling_thread.raise_exceptions()
  File "/usr/local/lib/python3.10/dist-packages/telebot/util.py", line 111, in raise_exceptions
    raise self.exception_info
  File "/usr/local/lib/python3.10/dist-packages/telebot/util.py", line 93, in run
    task(*args, **kwargs)
  File "/usr/local/lib/python3.10/dist-packages/telebot/__init__.py", line 688, in __retrieve_updates
    updates = self.get_updates(offset=(self.last_update_id + 1),
  File "/usr/local/lib/python3.10/dist-packages/telebot/__init__.py", line 660, in get_updates
    json_updates = apihelper.get_updates(
  File "/usr/local/lib/python3.10/dist-packages/telebot/apihelper.py", line 332, in get_updates
    return _make_request(token, method_url, params=payload)
  File "/usr/local/lib/python3.10/dist-packages/telebot/apihelper.py", line 162, in _make_request
    result = _get_req_session().request(
  File "/usr/lib/python3/dist-packages/requests/sessions.py", line 544, in request
    resp = self.send(prep, **send_kwargs)
  File "/usr/lib/python3/dist-packages/requests/sessions.py", line 657, in send
    r = adapter.send(request, **kwargs)
  File "/usr/lib/python3/dist-packages/requests/adapters.py", line 529, in send
    raise ReadTimeout(e, request=request)
requests.exceptions.ReadTimeout: HTTPSConnectionPool(host='api.telegram.org', port=443): Read timed out. (read timeout=10)
"
2025-02-07 19:20:25,910 (__init__.py:1115 MainThread) ERROR - TeleBot: "Infinity polling exception: 7757690184"
2025-02-07 19:20:25,913 (__init__.py:1117 MainThread) ERROR - TeleBot: "Exception traceback:
Traceback (most recent call last):
  File "/usr/local/lib/python3.10/dist-packages/telebot/__init__.py", line 1110, in infinity_polling
    self.polling(non_stop=True, timeout=timeout, long_polling_timeout=long_polling_timeout,
  File "/usr/local/lib/python3.10/dist-packages/telebot/__init__.py", line 1198, in polling
    self.__threaded_polling(non_stop=non_stop, interval=interval, timeout=timeout, long_polling_timeout=long_polling_timeout,
  File "/usr/local/lib/python3.10/dist-packages/telebot/__init__.py", line 1273, in __threaded_polling
    raise e
  File "/usr/local/lib/python3.10/dist-packages/telebot/__init__.py", line 1235, in __threaded_polling
    self.worker_pool.raise_exceptions()
  File "/usr/local/lib/python3.10/dist-packages/telebot/util.py", line 150, in raise_exceptions
    raise self.exception_info
  File "/usr/local/lib/python3.10/dist-packages/telebot/util.py", line 93, in run
    task(*args, **kwargs)
  File "/usr/local/lib/python3.10/dist-packages/telebot/__init__.py", line 9233, in _run_middlewares_and_handler
    result = handler['function'](message)
  File "/root/TelegramBot/body.py", line 32, in handle_answers
    process_answer(bot, message)
  File "/root/TelegramBot/functions.py", line 202, in process_answer
    del user_question_state[user_id]
KeyError: 7757690184
"
2025-02-09 13:36:33,932 (__init__.py:1115 MainThread) ERROR - TeleBot: "Infinity polling exception: ('Connection aborted.', ConnectionResetError(104, 'Connection reset by peer'))"
2025-02-09 13:36:33,934 (__init__.py:1117 MainThread) ERROR - TeleBot: "Exception traceback:
Traceback (most recent call last):
  File "/usr/lib/python3.10/ssl.py", line 1050, in _create
    self.getpeername()
OSError: [Errno 107] Transport endpoint is not connected

During handling of the above exception, another exception occurred:

Traceback (most recent call last):
  File "/usr/lib/python3/dist-packages/urllib3/connectionpool.py", line 700, in urlopen
    httplib_response = self._make_request(
  File "/usr/lib/python3/dist-packages/urllib3/connectionpool.py", line 383, in _make_request
    self._validate_conn(conn)
  File "/usr/lib/python3/dist-packages/urllib3/connectionpool.py", line 1017, in _validate_conn
    conn.connect()
  File "/usr/lib/python3/dist-packages/urllib3/connection.py", line 411, in connect
    self.sock = ssl_wrap_socket(
  File "/usr/lib/python3/dist-packages/urllib3/util/ssl_.py", line 449, in ssl_wrap_socket
    ssl_sock = _ssl_wrap_socket_impl(
  File "/usr/lib/python3/dist-packages/urllib3/util/ssl_.py", line 493, in _ssl_wrap_socket_impl
    return ssl_context.wrap_socket(sock, server_hostname=server_hostname)
  File "/usr/lib/python3.10/ssl.py", line 513, in wrap_socket
    return self.sslsocket_class._create(
  File "/usr/lib/python3.10/ssl.py", line 1062, in _create
    notconn_pre_handshake_data = self.recv(1)
  File "/usr/lib/python3.10/ssl.py", line 1290, in recv
    return super().recv(buflen, flags)
ConnectionResetError: [Errno 104] Connection reset by peer

During handling of the above exception, another exception occurred:

Traceback (most recent call last):
  File "/usr/lib/python3/dist-packages/requests/adapters.py", line 439, in send
    resp = conn.urlopen(
  File "/usr/lib/python3/dist-packages/urllib3/connectionpool.py", line 756, in urlopen
    retries = retries.increment(
  File "/usr/lib/python3/dist-packages/urllib3/util/retry.py", line 534, in increment
    raise six.reraise(type(error), error, _stacktrace)
  File "/usr/lib/python3/dist-packages/six.py", line 718, in reraise
    raise value.with_traceback(tb)
  File "/usr/lib/python3/dist-packages/urllib3/connectionpool.py", line 700, in urlopen
    httplib_response = self._make_request(
  File "/usr/lib/python3/dist-packages/urllib3/connectionpool.py", line 383, in _make_request
    self._validate_conn(conn)
  File "/usr/lib/python3/dist-packages/urllib3/connectionpool.py", line 1017, in _validate_conn
    conn.connect()
  File "/usr/lib/python3/dist-packages/urllib3/connection.py", line 411, in connect
    self.sock = ssl_wrap_socket(
  File "/usr/lib/python3/dist-packages/urllib3/util/ssl_.py", line 449, in ssl_wrap_socket
    ssl_sock = _ssl_wrap_socket_impl(
  File "/usr/lib/python3/dist-packages/urllib3/util/ssl_.py", line 493, in _ssl_wrap_socket_impl
    return ssl_context.wrap_socket(sock, server_hostname=server_hostname)
  File "/usr/lib/python3.10/ssl.py", line 513, in wrap_socket
    return self.sslsocket_class._create(
  File "/usr/lib/python3.10/ssl.py", line 1062, in _create
    notconn_pre_handshake_data = self.recv(1)
  File "/usr/lib/python3.10/ssl.py", line 1290, in recv
    return super().recv(buflen, flags)
urllib3.exceptions.ProtocolError: ('Connection aborted.', ConnectionResetError(104, 'Connection reset by peer'))

During handling of the above exception, another exception occurred:

Traceback (most recent call last):
  File "/usr/local/lib/python3.10/dist-packages/telebot/__init__.py", line 1110, in infinity_polling
    self.polling(non_stop=True, timeout=timeout, long_polling_timeout=long_polling_timeout,
  File "/usr/local/lib/python3.10/dist-packages/telebot/__init__.py", line 1198, in polling
    self.__threaded_polling(non_stop=non_stop, interval=interval, timeout=timeout, long_polling_timeout=long_polling_timeout,
  File "/usr/local/lib/python3.10/dist-packages/telebot/__init__.py", line 1273, in __threaded_polling
    raise e
  File "/usr/local/lib/python3.10/dist-packages/telebot/__init__.py", line 1234, in __threaded_polling
    polling_thread.raise_exceptions()
  File "/usr/local/lib/python3.10/dist-packages/telebot/util.py", line 111, in raise_exceptions
    raise self.exception_info
  File "/usr/local/lib/python3.10/dist-packages/telebot/util.py", line 93, in run
    task(*args, **kwargs)
  File "/usr/local/lib/python3.10/dist-packages/telebot/__init__.py", line 688, in __retrieve_updates
    updates = self.get_updates(offset=(self.last_update_id + 1),
  File "/usr/local/lib/python3.10/dist-packages/telebot/__init__.py", line 660, in get_updates
    json_updates = apihelper.get_updates(
  File "/usr/local/lib/python3.10/dist-packages/telebot/apihelper.py", line 332, in get_updates
    return _make_request(token, method_url, params=payload)
  File "/usr/local/lib/python3.10/dist-packages/telebot/apihelper.py", line 162, in _make_request
    result = _get_req_session().request(
  File "/usr/lib/python3/dist-packages/requests/sessions.py", line 544, in request
    resp = self.send(prep, **send_kwargs)
  File "/usr/lib/python3/dist-packages/requests/sessions.py", line 657, in send
    r = adapter.send(request, **kwargs)
  File "/usr/lib/python3/dist-packages/requests/adapters.py", line 498, in send
    raise ConnectionError(err, request=request)
requests.exceptions.ConnectionError: ('Connection aborted.', ConnectionResetError(104, 'Connection reset by peer'))
"
2025-02-09 13:40:46,985 (__init__.py:1115 MainThread) ERROR - TeleBot: "Infinity polling exception: HTTPSConnectionPool(host='api.telegram.org', port=443): Read timed out. (read timeout=10)"
2025-02-09 13:40:46,986 (__init__.py:1117 MainThread) ERROR - TeleBot: "Exception traceback:
Traceback (most recent call last):
  File "/usr/lib/python3/dist-packages/urllib3/connectionpool.py", line 446, in _make_request
    six.raise_from(e, None)
  File "<string>", line 3, in raise_from
  File "/usr/lib/python3/dist-packages/urllib3/connectionpool.py", line 441, in _make_request
    httplib_response = conn.getresponse()
  File "/usr/lib/python3.10/http/client.py", line 1375, in getresponse
    response.begin()
  File "/usr/lib/python3.10/http/client.py", line 318, in begin
    version, status, reason = self._read_status()
  File "/usr/lib/python3.10/http/client.py", line 279, in _read_status
    line = str(self.fp.readline(_MAXLINE + 1), "iso-8859-1")
  File "/usr/lib/python3.10/socket.py", line 705, in readinto
    return self._sock.recv_into(b)
  File "/usr/lib/python3.10/ssl.py", line 1303, in recv_into
    return self.read(nbytes, buffer)
  File "/usr/lib/python3.10/ssl.py", line 1159, in read
    return self._sslobj.read(len, buffer)
TimeoutError: The read operation timed out

During handling of the above exception, another exception occurred:

Traceback (most recent call last):
  File "/usr/lib/python3/dist-packages/requests/adapters.py", line 439, in send
    resp = conn.urlopen(
  File "/usr/lib/python3/dist-packages/urllib3/connectionpool.py", line 756, in urlopen
    retries = retries.increment(
  File "/usr/lib/python3/dist-packages/urllib3/util/retry.py", line 534, in increment
    raise six.reraise(type(error), error, _stacktrace)
  File "/usr/lib/python3/dist-packages/six.py", line 719, in reraise
    raise value
  File "/usr/lib/python3/dist-packages/urllib3/connectionpool.py", line 700, in urlopen
    httplib_response = self._make_request(
  File "/usr/lib/python3/dist-packages/urllib3/connectionpool.py", line 448, in _make_request
    self._raise_timeout(err=e, url=url, timeout_value=read_timeout)
  File "/usr/lib/python3/dist-packages/urllib3/connectionpool.py", line 337, in _raise_timeout
    raise ReadTimeoutError(
urllib3.exceptions.ReadTimeoutError: HTTPSConnectionPool(host='api.telegram.org', port=443): Read timed out. (read timeout=10)

During handling of the above exception, another exception occurred:

Traceback (most recent call last):
  File "/usr/local/lib/python3.10/dist-packages/telebot/__init__.py", line 1110, in infinity_polling
    self.polling(non_stop=True, timeout=timeout, long_polling_timeout=long_polling_timeout,
  File "/usr/local/lib/python3.10/dist-packages/telebot/__init__.py", line 1198, in polling
    self.__threaded_polling(non_stop=non_stop, interval=interval, timeout=timeout, long_polling_timeout=long_polling_timeout,
  File "/usr/local/lib/python3.10/dist-packages/telebot/__init__.py", line 1273, in __threaded_polling
    raise e
  File "/usr/local/lib/python3.10/dist-packages/telebot/__init__.py", line 1234, in __threaded_polling
    polling_thread.raise_exceptions()
  File "/usr/local/lib/python3.10/dist-packages/telebot/util.py", line 111, in raise_exceptions
    raise self.exception_info
  File "/usr/local/lib/python3.10/dist-packages/telebot/util.py", line 93, in run
    task(*args, **kwargs)
  File "/usr/local/lib/python3.10/dist-packages/telebot/__init__.py", line 688, in __retrieve_updates
    updates = self.get_updates(offset=(self.last_update_id + 1),
  File "/usr/local/lib/python3.10/dist-packages/telebot/__init__.py", line 660, in get_updates
    json_updates = apihelper.get_updates(
  File "/usr/local/lib/python3.10/dist-packages/telebot/apihelper.py", line 332, in get_updates
    return _make_request(token, method_url, params=payload)
  File "/usr/local/lib/python3.10/dist-packages/telebot/apihelper.py", line 162, in _make_request
    result = _get_req_session().request(
  File "/usr/lib/python3/dist-packages/requests/sessions.py", line 544, in request
    resp = self.send(prep, **send_kwargs)
  File "/usr/lib/python3/dist-packages/requests/sessions.py", line 657, in send
    r = adapter.send(request, **kwargs)
  File "/usr/lib/python3/dist-packages/requests/adapters.py", line 529, in send
    raise ReadTimeout(e, request=request)
requests.exceptions.ReadTimeout: HTTPSConnectionPool(host='api.telegram.org', port=443): Read timed out. (read timeout=10)
"
2025-02-09 13:49:49,192 (__init__.py:1115 MainThread) ERROR - TeleBot: "Infinity polling exception: ('Connection aborted.', RemoteDisconnected('Remote end closed connection without response'))"
2025-02-09 13:49:49,193 (__init__.py:1117 MainThread) ERROR - TeleBot: "Exception traceback:
Traceback (most recent call last):
  File "/usr/lib/python3/dist-packages/urllib3/connectionpool.py", line 700, in urlopen
    httplib_response = self._make_request(
  File "/usr/lib/python3/dist-packages/urllib3/connectionpool.py", line 446, in _make_request
    six.raise_from(e, None)
  File "<string>", line 3, in raise_from
  File "/usr/lib/python3/dist-packages/urllib3/connectionpool.py", line 441, in _make_request
    httplib_response = conn.getresponse()
  File "/usr/lib/python3.10/http/client.py", line 1375, in getresponse
    response.begin()
  File "/usr/lib/python3.10/http/client.py", line 318, in begin
    version, status, reason = self._read_status()
  File "/usr/lib/python3.10/http/client.py", line 287, in _read_status
    raise RemoteDisconnected("Remote end closed connection without"
http.client.RemoteDisconnected: Remote end closed connection without response

During handling of the above exception, another exception occurred:

Traceback (most recent call last):
  File "/usr/lib/python3/dist-packages/requests/adapters.py", line 439, in send
    resp = conn.urlopen(
  File "/usr/lib/python3/dist-packages/urllib3/connectionpool.py", line 756, in urlopen
    retries = retries.increment(
  File "/usr/lib/python3/dist-packages/urllib3/util/retry.py", line 534, in increment
    raise six.reraise(type(error), error, _stacktrace)
  File "/usr/lib/python3/dist-packages/six.py", line 718, in reraise
    raise value.with_traceback(tb)
  File "/usr/lib/python3/dist-packages/urllib3/connectionpool.py", line 700, in urlopen
    httplib_response = self._make_request(
  File "/usr/lib/python3/dist-packages/urllib3/connectionpool.py", line 446, in _make_request
    six.raise_from(e, None)
  File "<string>", line 3, in raise_from
  File "/usr/lib/python3/dist-packages/urllib3/connectionpool.py", line 441, in _make_request
    httplib_response = conn.getresponse()
  File "/usr/lib/python3.10/http/client.py", line 1375, in getresponse
    response.begin()
  File "/usr/lib/python3.10/http/client.py", line 318, in begin
    version, status, reason = self._read_status()
  File "/usr/lib/python3.10/http/client.py", line 287, in _read_status
    raise RemoteDisconnected("Remote end closed connection without"
urllib3.exceptions.ProtocolError: ('Connection aborted.', RemoteDisconnected('Remote end closed connection without response'))

During handling of the above exception, another exception occurred:

Traceback (most recent call last):
  File "/usr/local/lib/python3.10/dist-packages/telebot/__init__.py", line 1110, in infinity_polling
    self.polling(non_stop=True, timeout=timeout, long_polling_timeout=long_polling_timeout,
  File "/usr/local/lib/python3.10/dist-packages/telebot/__init__.py", line 1198, in polling
    self.__threaded_polling(non_stop=non_stop, interval=interval, timeout=timeout, long_polling_timeout=long_polling_timeout,
  File "/usr/local/lib/python3.10/dist-packages/telebot/__init__.py", line 1273, in __threaded_polling
    raise e
  File "/usr/local/lib/python3.10/dist-packages/telebot/__init__.py", line 1234, in __threaded_polling
    polling_thread.raise_exceptions()
  File "/usr/local/lib/python3.10/dist-packages/telebot/util.py", line 111, in raise_exceptions
    raise self.exception_info
  File "/usr/local/lib/python3.10/dist-packages/telebot/util.py", line 93, in run
    task(*args, **kwargs)
  File "/usr/local/lib/python3.10/dist-packages/telebot/__init__.py", line 688, in __retrieve_updates
    updates = self.get_updates(offset=(self.last_update_id + 1),
  File "/usr/local/lib/python3.10/dist-packages/telebot/__init__.py", line 660, in get_updates
    json_updates = apihelper.get_updates(
  File "/usr/local/lib/python3.10/dist-packages/telebot/apihelper.py", line 332, in get_updates
    return _make_request(token, method_url, params=payload)
  File "/usr/local/lib/python3.10/dist-packages/telebot/apihelper.py", line 162, in _make_request
    result = _get_req_session().request(
  File "/usr/lib/python3/dist-packages/requests/sessions.py", line 544, in request
    resp = self.send(prep, **send_kwargs)
  File "/usr/lib/python3/dist-packages/requests/sessions.py", line 657, in send
    r = adapter.send(request, **kwargs)
  File "/usr/lib/python3/dist-packages/requests/adapters.py", line 498, in send
    raise ConnectionError(err, request=request)
requests.exceptions.ConnectionError: ('Connection aborted.', RemoteDisconnected('Remote end closed connection without response'))
"
2025-02-09 14:21:29,460 (__init__.py:1115 MainThread) ERROR - TeleBot: "Infinity polling exception: HTTPSConnectionPool(host='api.telegram.org', port=443): Read timed out. (read timeout=10)"
2025-02-09 14:21:29,461 (__init__.py:1117 MainThread) ERROR - TeleBot: "Exception traceback:
Traceback (most recent call last):
  File "/usr/lib/python3/dist-packages/urllib3/connectionpool.py", line 446, in _make_request
    six.raise_from(e, None)
  File "<string>", line 3, in raise_from
  File "/usr/lib/python3/dist-packages/urllib3/connectionpool.py", line 441, in _make_request
    httplib_response = conn.getresponse()
  File "/usr/lib/python3.10/http/client.py", line 1375, in getresponse
    response.begin()
  File "/usr/lib/python3.10/http/client.py", line 318, in begin
    version, status, reason = self._read_status()
  File "/usr/lib/python3.10/http/client.py", line 279, in _read_status
    line = str(self.fp.readline(_MAXLINE + 1), "iso-8859-1")
  File "/usr/lib/python3.10/socket.py", line 705, in readinto
    return self._sock.recv_into(b)
  File "/usr/lib/python3.10/ssl.py", line 1303, in recv_into
    return self.read(nbytes, buffer)
  File "/usr/lib/python3.10/ssl.py", line 1159, in read
    return self._sslobj.read(len, buffer)
TimeoutError: The read operation timed out

During handling of the above exception, another exception occurred:

Traceback (most recent call last):
  File "/usr/lib/python3/dist-packages/requests/adapters.py", line 439, in send
    resp = conn.urlopen(
  File "/usr/lib/python3/dist-packages/urllib3/connectionpool.py", line 756, in urlopen
    retries = retries.increment(
  File "/usr/lib/python3/dist-packages/urllib3/util/retry.py", line 534, in increment
    raise six.reraise(type(error), error, _stacktrace)
  File "/usr/lib/python3/dist-packages/six.py", line 719, in reraise
    raise value
  File "/usr/lib/python3/dist-packages/urllib3/connectionpool.py", line 700, in urlopen
    httplib_response = self._make_request(
  File "/usr/lib/python3/dist-packages/urllib3/connectionpool.py", line 448, in _make_request
    self._raise_timeout(err=e, url=url, timeout_value=read_timeout)
  File "/usr/lib/python3/dist-packages/urllib3/connectionpool.py", line 337, in _raise_timeout
    raise ReadTimeoutError(
urllib3.exceptions.ReadTimeoutError: HTTPSConnectionPool(host='api.telegram.org', port=443): Read timed out. (read timeout=10)

During handling of the above exception, another exception occurred:

Traceback (most recent call last):
  File "/usr/local/lib/python3.10/dist-packages/telebot/__init__.py", line 1110, in infinity_polling
    self.polling(non_stop=True, timeout=timeout, long_polling_timeout=long_polling_timeout,
  File "/usr/local/lib/python3.10/dist-packages/telebot/__init__.py", line 1198, in polling
    self.__threaded_polling(non_stop=non_stop, interval=interval, timeout=timeout, long_polling_timeout=long_polling_timeout,
  File "/usr/local/lib/python3.10/dist-packages/telebot/__init__.py", line 1273, in __threaded_polling
    raise e
  File "/usr/local/lib/python3.10/dist-packages/telebot/__init__.py", line 1234, in __threaded_polling
    polling_thread.raise_exceptions()
  File "/usr/local/lib/python3.10/dist-packages/telebot/util.py", line 111, in raise_exceptions
    raise self.exception_info
  File "/usr/local/lib/python3.10/dist-packages/telebot/util.py", line 93, in run
    task(*args, **kwargs)
  File "/usr/local/lib/python3.10/dist-packages/telebot/__init__.py", line 688, in __retrieve_updates
    updates = self.get_updates(offset=(self.last_update_id + 1),
  File "/usr/local/lib/python3.10/dist-packages/telebot/__init__.py", line 660, in get_updates
    json_updates = apihelper.get_updates(
  File "/usr/local/lib/python3.10/dist-packages/telebot/apihelper.py", line 332, in get_updates
    return _make_request(token, method_url, params=payload)
  File "/usr/local/lib/python3.10/dist-packages/telebot/apihelper.py", line 162, in _make_request
    result = _get_req_session().request(
  File "/usr/lib/python3/dist-packages/requests/sessions.py", line 544, in request
    resp = self.send(prep, **send_kwargs)
  File "/usr/lib/python3/dist-packages/requests/sessions.py", line 657, in send
    r = adapter.send(request, **kwargs)
  File "/usr/lib/python3/dist-packages/requests/adapters.py", line 529, in send
    raise ReadTimeout(e, request=request)
requests.exceptions.ReadTimeout: HTTPSConnectionPool(host='api.telegram.org', port=443): Read timed out. (read timeout=10)
"
2025-02-09 14:56:05,398 (__init__.py:1115 MainThread) ERROR - TeleBot: "Infinity polling exception: ('Connection aborted.', RemoteDisconnected('Remote end closed connection without response'))"
2025-02-09 14:56:05,398 (__init__.py:1117 MainThread) ERROR - TeleBot: "Exception traceback:
Traceback (most recent call last):
  File "/usr/lib/python3/dist-packages/urllib3/connectionpool.py", line 700, in urlopen
    httplib_response = self._make_request(
  File "/usr/lib/python3/dist-packages/urllib3/connectionpool.py", line 446, in _make_request
    six.raise_from(e, None)
  File "<string>", line 3, in raise_from
  File "/usr/lib/python3/dist-packages/urllib3/connectionpool.py", line 441, in _make_request
    httplib_response = conn.getresponse()
  File "/usr/lib/python3.10/http/client.py", line 1375, in getresponse
    response.begin()
  File "/usr/lib/python3.10/http/client.py", line 318, in begin
    version, status, reason = self._read_status()
  File "/usr/lib/python3.10/http/client.py", line 287, in _read_status
    raise RemoteDisconnected("Remote end closed connection without"
http.client.RemoteDisconnected: Remote end closed connection without response

During handling of the above exception, another exception occurred:

Traceback (most recent call last):
  File "/usr/lib/python3/dist-packages/requests/adapters.py", line 439, in send
    resp = conn.urlopen(
  File "/usr/lib/python3/dist-packages/urllib3/connectionpool.py", line 756, in urlopen
    retries = retries.increment(
  File "/usr/lib/python3/dist-packages/urllib3/util/retry.py", line 534, in increment
    raise six.reraise(type(error), error, _stacktrace)
  File "/usr/lib/python3/dist-packages/six.py", line 718, in reraise
    raise value.with_traceback(tb)
  File "/usr/lib/python3/dist-packages/urllib3/connectionpool.py", line 700, in urlopen
    httplib_response = self._make_request(
  File "/usr/lib/python3/dist-packages/urllib3/connectionpool.py", line 446, in _make_request
    six.raise_from(e, None)
  File "<string>", line 3, in raise_from
  File "/usr/lib/python3/dist-packages/urllib3/connectionpool.py", line 441, in _make_request
    httplib_response = conn.getresponse()
  File "/usr/lib/python3.10/http/client.py", line 1375, in getresponse
    response.begin()
  File "/usr/lib/python3.10/http/client.py", line 318, in begin
    version, status, reason = self._read_status()
  File "/usr/lib/python3.10/http/client.py", line 287, in _read_status
    raise RemoteDisconnected("Remote end closed connection without"
urllib3.exceptions.ProtocolError: ('Connection aborted.', RemoteDisconnected('Remote end closed connection without response'))

During handling of the above exception, another exception occurred:

Traceback (most recent call last):
  File "/usr/local/lib/python3.10/dist-packages/telebot/__init__.py", line 1110, in infinity_polling
    self.polling(non_stop=True, timeout=timeout, long_polling_timeout=long_polling_timeout,
  File "/usr/local/lib/python3.10/dist-packages/telebot/__init__.py", line 1198, in polling
    self.__threaded_polling(non_stop=non_stop, interval=interval, timeout=timeout, long_polling_timeout=long_polling_timeout,
  File "/usr/local/lib/python3.10/dist-packages/telebot/__init__.py", line 1273, in __threaded_polling
    raise e
  File "/usr/local/lib/python3.10/dist-packages/telebot/__init__.py", line 1234, in __threaded_polling
    polling_thread.raise_exceptions()
  File "/usr/local/lib/python3.10/dist-packages/telebot/util.py", line 111, in raise_exceptions
    raise self.exception_info
  File "/usr/local/lib/python3.10/dist-packages/telebot/util.py", line 93, in run
    task(*args, **kwargs)
  File "/usr/local/lib/python3.10/dist-packages/telebot/__init__.py", line 688, in __retrieve_updates
    updates = self.get_updates(offset=(self.last_update_id + 1),
  File "/usr/local/lib/python3.10/dist-packages/telebot/__init__.py", line 660, in get_updates
    json_updates = apihelper.get_updates(
  File "/usr/local/lib/python3.10/dist-packages/telebot/apihelper.py", line 332, in get_updates
    return _make_request(token, method_url, params=payload)
  File "/usr/local/lib/python3.10/dist-packages/telebot/apihelper.py", line 162, in _make_request
    result = _get_req_session().request(
  File "/usr/lib/python3/dist-packages/requests/sessions.py", line 544, in request
    resp = self.send(prep, **send_kwargs)
  File "/usr/lib/python3/dist-packages/requests/sessions.py", line 657, in send
    r = adapter.send(request, **kwargs)
  File "/usr/lib/python3/dist-packages/requests/adapters.py", line 498, in send
    raise ConnectionError(err, request=request)
requests.exceptions.ConnectionError: ('Connection aborted.', RemoteDisconnected('Remote end closed connection without response'))
"
2025-02-09 15:05:35,285 (__init__.py:1115 MainThread) ERROR - TeleBot: "Infinity polling exception: HTTPSConnectionPool(host='api.telegram.org', port=443): Read timed out. (read timeout=10)"
2025-02-09 15:05:35,286 (__init__.py:1117 MainThread) ERROR - TeleBot: "Exception traceback:
Traceback (most recent call last):
  File "/usr/lib/python3/dist-packages/urllib3/connectionpool.py", line 446, in _make_request
    six.raise_from(e, None)
  File "<string>", line 3, in raise_from
  File "/usr/lib/python3/dist-packages/urllib3/connectionpool.py", line 441, in _make_request
    httplib_response = conn.getresponse()
  File "/usr/lib/python3.10/http/client.py", line 1375, in getresponse
    response.begin()
  File "/usr/lib/python3.10/http/client.py", line 318, in begin
    version, status, reason = self._read_status()
  File "/usr/lib/python3.10/http/client.py", line 279, in _read_status
    line = str(self.fp.readline(_MAXLINE + 1), "iso-8859-1")
  File "/usr/lib/python3.10/socket.py", line 705, in readinto
    return self._sock.recv_into(b)
  File "/usr/lib/python3.10/ssl.py", line 1303, in recv_into
    return self.read(nbytes, buffer)
  File "/usr/lib/python3.10/ssl.py", line 1159, in read
    return self._sslobj.read(len, buffer)
TimeoutError: The read operation timed out

During handling of the above exception, another exception occurred:

Traceback (most recent call last):
  File "/usr/lib/python3/dist-packages/requests/adapters.py", line 439, in send
    resp = conn.urlopen(
  File "/usr/lib/python3/dist-packages/urllib3/connectionpool.py", line 756, in urlopen
    retries = retries.increment(
  File "/usr/lib/python3/dist-packages/urllib3/util/retry.py", line 534, in increment
    raise six.reraise(type(error), error, _stacktrace)
  File "/usr/lib/python3/dist-packages/six.py", line 719, in reraise
    raise value
  File "/usr/lib/python3/dist-packages/urllib3/connectionpool.py", line 700, in urlopen
    httplib_response = self._make_request(
  File "/usr/lib/python3/dist-packages/urllib3/connectionpool.py", line 448, in _make_request
    self._raise_timeout(err=e, url=url, timeout_value=read_timeout)
  File "/usr/lib/python3/dist-packages/urllib3/connectionpool.py", line 337, in _raise_timeout
    raise ReadTimeoutError(
urllib3.exceptions.ReadTimeoutError: HTTPSConnectionPool(host='api.telegram.org', port=443): Read timed out. (read timeout=10)

During handling of the above exception, another exception occurred:

Traceback (most recent call last):
  File "/usr/local/lib/python3.10/dist-packages/telebot/__init__.py", line 1110, in infinity_polling
    self.polling(non_stop=True, timeout=timeout, long_polling_timeout=long_polling_timeout,
  File "/usr/local/lib/python3.10/dist-packages/telebot/__init__.py", line 1198, in polling
    self.__threaded_polling(non_stop=non_stop, interval=interval, timeout=timeout, long_polling_timeout=long_polling_timeout,
  File "/usr/local/lib/python3.10/dist-packages/telebot/__init__.py", line 1273, in __threaded_polling
    raise e
  File "/usr/local/lib/python3.10/dist-packages/telebot/__init__.py", line 1234, in __threaded_polling
    polling_thread.raise_exceptions()
  File "/usr/local/lib/python3.10/dist-packages/telebot/util.py", line 111, in raise_exceptions
    raise self.exception_info
  File "/usr/local/lib/python3.10/dist-packages/telebot/util.py", line 93, in run
    task(*args, **kwargs)
  File "/usr/local/lib/python3.10/dist-packages/telebot/__init__.py", line 688, in __retrieve_updates
    updates = self.get_updates(offset=(self.last_update_id + 1),
  File "/usr/local/lib/python3.10/dist-packages/telebot/__init__.py", line 660, in get_updates
    json_updates = apihelper.get_updates(
  File "/usr/local/lib/python3.10/dist-packages/telebot/apihelper.py", line 332, in get_updates
    return _make_request(token, method_url, params=payload)
  File "/usr/local/lib/python3.10/dist-packages/telebot/apihelper.py", line 162, in _make_request
    result = _get_req_session().request(
  File "/usr/lib/python3/dist-packages/requests/sessions.py", line 544, in request
    resp = self.send(prep, **send_kwargs)
  File "/usr/lib/python3/dist-packages/requests/sessions.py", line 657, in send
    r = adapter.send(request, **kwargs)
  File "/usr/lib/python3/dist-packages/requests/adapters.py", line 529, in send
    raise ReadTimeout(e, request=request)
requests.exceptions.ReadTimeout: HTTPSConnectionPool(host='api.telegram.org', port=443): Read timed out. (read timeout=10)
"
2025-02-09 15:12:26,562 (__init__.py:1115 MainThread) ERROR - TeleBot: "Infinity polling exception: ('Connection aborted.', RemoteDisconnected('Remote end closed connection without response'))"
2025-02-09 15:12:26,562 (__init__.py:1117 MainThread) ERROR - TeleBot: "Exception traceback:
Traceback (most recent call last):
  File "/usr/lib/python3/dist-packages/urllib3/connectionpool.py", line 700, in urlopen
    httplib_response = self._make_request(
  File "/usr/lib/python3/dist-packages/urllib3/connectionpool.py", line 446, in _make_request
    six.raise_from(e, None)
  File "<string>", line 3, in raise_from
  File "/usr/lib/python3/dist-packages/urllib3/connectionpool.py", line 441, in _make_request
    httplib_response = conn.getresponse()
  File "/usr/lib/python3.10/http/client.py", line 1375, in getresponse
    response.begin()
  File "/usr/lib/python3.10/http/client.py", line 318, in begin
    version, status, reason = self._read_status()
  File "/usr/lib/python3.10/http/client.py", line 287, in _read_status
    raise RemoteDisconnected("Remote end closed connection without"
http.client.RemoteDisconnected: Remote end closed connection without response

During handling of the above exception, another exception occurred:

Traceback (most recent call last):
  File "/usr/lib/python3/dist-packages/requests/adapters.py", line 439, in send
    resp = conn.urlopen(
  File "/usr/lib/python3/dist-packages/urllib3/connectionpool.py", line 756, in urlopen
    retries = retries.increment(
  File "/usr/lib/python3/dist-packages/urllib3/util/retry.py", line 534, in increment
    raise six.reraise(type(error), error, _stacktrace)
  File "/usr/lib/python3/dist-packages/six.py", line 718, in reraise
    raise value.with_traceback(tb)
  File "/usr/lib/python3/dist-packages/urllib3/connectionpool.py", line 700, in urlopen
    httplib_response = self._make_request(
  File "/usr/lib/python3/dist-packages/urllib3/connectionpool.py", line 446, in _make_request
    six.raise_from(e, None)
  File "<string>", line 3, in raise_from
  File "/usr/lib/python3/dist-packages/urllib3/connectionpool.py", line 441, in _make_request
    httplib_response = conn.getresponse()
  File "/usr/lib/python3.10/http/client.py", line 1375, in getresponse
    response.begin()
  File "/usr/lib/python3.10/http/client.py", line 318, in begin
    version, status, reason = self._read_status()
  File "/usr/lib/python3.10/http/client.py", line 287, in _read_status
    raise RemoteDisconnected("Remote end closed connection without"
urllib3.exceptions.ProtocolError: ('Connection aborted.', RemoteDisconnected('Remote end closed connection without response'))

During handling of the above exception, another exception occurred:

Traceback (most recent call last):
  File "/usr/local/lib/python3.10/dist-packages/telebot/__init__.py", line 1110, in infinity_polling
    self.polling(non_stop=True, timeout=timeout, long_polling_timeout=long_polling_timeout,
  File "/usr/local/lib/python3.10/dist-packages/telebot/__init__.py", line 1198, in polling
    self.__threaded_polling(non_stop=non_stop, interval=interval, timeout=timeout, long_polling_timeout=long_polling_timeout,
  File "/usr/local/lib/python3.10/dist-packages/telebot/__init__.py", line 1273, in __threaded_polling
    raise e
  File "/usr/local/lib/python3.10/dist-packages/telebot/__init__.py", line 1234, in __threaded_polling
    polling_thread.raise_exceptions()
  File "/usr/local/lib/python3.10/dist-packages/telebot/util.py", line 111, in raise_exceptions
    raise self.exception_info
  File "/usr/local/lib/python3.10/dist-packages/telebot/util.py", line 93, in run
    task(*args, **kwargs)
  File "/usr/local/lib/python3.10/dist-packages/telebot/__init__.py", line 688, in __retrieve_updates
    updates = self.get_updates(offset=(self.last_update_id + 1),
  File "/usr/local/lib/python3.10/dist-packages/telebot/__init__.py", line 660, in get_updates
    json_updates = apihelper.get_updates(
  File "/usr/local/lib/python3.10/dist-packages/telebot/apihelper.py", line 332, in get_updates
    return _make_request(token, method_url, params=payload)
  File "/usr/local/lib/python3.10/dist-packages/telebot/apihelper.py", line 162, in _make_request
    result = _get_req_session().request(
  File "/usr/lib/python3/dist-packages/requests/sessions.py", line 544, in request
    resp = self.send(prep, **send_kwargs)
  File "/usr/lib/python3/dist-packages/requests/sessions.py", line 657, in send
    r = adapter.send(request, **kwargs)
  File "/usr/lib/python3/dist-packages/requests/adapters.py", line 498, in send
    raise ConnectionError(err, request=request)
requests.exceptions.ConnectionError: ('Connection aborted.', RemoteDisconnected('Remote end closed connection without response'))
"
2025-02-10 03:47:24,474 (__init__.py:1115 MainThread) ERROR - TeleBot: "Infinity polling exception: ('Connection aborted.', RemoteDisconnected('Remote end closed connection without response'))"
2025-02-10 03:47:24,475 (__init__.py:1117 MainThread) ERROR - TeleBot: "Exception traceback:
Traceback (most recent call last):
  File "/usr/lib/python3/dist-packages/urllib3/connectionpool.py", line 700, in urlopen
    httplib_response = self._make_request(
  File "/usr/lib/python3/dist-packages/urllib3/connectionpool.py", line 446, in _make_request
    six.raise_from(e, None)
  File "<string>", line 3, in raise_from
  File "/usr/lib/python3/dist-packages/urllib3/connectionpool.py", line 441, in _make_request
    httplib_response = conn.getresponse()
  File "/usr/lib/python3.10/http/client.py", line 1375, in getresponse
    response.begin()
  File "/usr/lib/python3.10/http/client.py", line 318, in begin
    version, status, reason = self._read_status()
  File "/usr/lib/python3.10/http/client.py", line 287, in _read_status
    raise RemoteDisconnected("Remote end closed connection without"
http.client.RemoteDisconnected: Remote end closed connection without response

During handling of the above exception, another exception occurred:

Traceback (most recent call last):
  File "/usr/lib/python3/dist-packages/requests/adapters.py", line 439, in send
    resp = conn.urlopen(
  File "/usr/lib/python3/dist-packages/urllib3/connectionpool.py", line 756, in urlopen
    retries = retries.increment(
  File "/usr/lib/python3/dist-packages/urllib3/util/retry.py", line 534, in increment
    raise six.reraise(type(error), error, _stacktrace)
  File "/usr/lib/python3/dist-packages/six.py", line 718, in reraise
    raise value.with_traceback(tb)
  File "/usr/lib/python3/dist-packages/urllib3/connectionpool.py", line 700, in urlopen
    httplib_response = self._make_request(
  File "/usr/lib/python3/dist-packages/urllib3/connectionpool.py", line 446, in _make_request
    six.raise_from(e, None)
  File "<string>", line 3, in raise_from
  File "/usr/lib/python3/dist-packages/urllib3/connectionpool.py", line 441, in _make_request
    httplib_response = conn.getresponse()
  File "/usr/lib/python3.10/http/client.py", line 1375, in getresponse
    response.begin()
  File "/usr/lib/python3.10/http/client.py", line 318, in begin
    version, status, reason = self._read_status()
  File "/usr/lib/python3.10/http/client.py", line 287, in _read_status
    raise RemoteDisconnected("Remote end closed connection without"
urllib3.exceptions.ProtocolError: ('Connection aborted.', RemoteDisconnected('Remote end closed connection without response'))

During handling of the above exception, another exception occurred:

Traceback (most recent call last):
  File "/usr/local/lib/python3.10/dist-packages/telebot/__init__.py", line 1110, in infinity_polling
    self.polling(non_stop=True, timeout=timeout, long_polling_timeout=long_polling_timeout,
  File "/usr/local/lib/python3.10/dist-packages/telebot/__init__.py", line 1198, in polling
    self.__threaded_polling(non_stop=non_stop, interval=interval, timeout=timeout, long_polling_timeout=long_polling_timeout,
  File "/usr/local/lib/python3.10/dist-packages/telebot/__init__.py", line 1273, in __threaded_polling
    raise e
  File "/usr/local/lib/python3.10/dist-packages/telebot/__init__.py", line 1234, in __threaded_polling
    polling_thread.raise_exceptions()
  File "/usr/local/lib/python3.10/dist-packages/telebot/util.py", line 111, in raise_exceptions
    raise self.exception_info
  File "/usr/local/lib/python3.10/dist-packages/telebot/util.py", line 93, in run
    task(*args, **kwargs)
  File "/usr/local/lib/python3.10/dist-packages/telebot/__init__.py", line 688, in __retrieve_updates
    updates = self.get_updates(offset=(self.last_update_id + 1),
  File "/usr/local/lib/python3.10/dist-packages/telebot/__init__.py", line 660, in get_updates
    json_updates = apihelper.get_updates(
  File "/usr/local/lib/python3.10/dist-packages/telebot/apihelper.py", line 332, in get_updates
    return _make_request(token, method_url, params=payload)
  File "/usr/local/lib/python3.10/dist-packages/telebot/apihelper.py", line 162, in _make_request
    result = _get_req_session().request(
  File "/usr/lib/python3/dist-packages/requests/sessions.py", line 544, in request
    resp = self.send(prep, **send_kwargs)
  File "/usr/lib/python3/dist-packages/requests/sessions.py", line 657, in send
    r = adapter.send(request, **kwargs)
  File "/usr/lib/python3/dist-packages/requests/adapters.py", line 498, in send
    raise ConnectionError(err, request=request)
requests.exceptions.ConnectionError: ('Connection aborted.', RemoteDisconnected('Remote end closed connection without response'))
"
2025-02-11 10:11:52,490 (__init__.py:1115 MainThread) ERROR - TeleBot: "Infinity polling exception: HTTPSConnectionPool(host='api.telegram.org', port=443): Read timed out. (read timeout=10)"
2025-02-11 10:11:52,492 (__init__.py:1117 MainThread) ERROR - TeleBot: "Exception traceback:
Traceback (most recent call last):
  File "/usr/lib/python3/dist-packages/urllib3/connectionpool.py", line 446, in _make_request
    six.raise_from(e, None)
  File "<string>", line 3, in raise_from
  File "/usr/lib/python3/dist-packages/urllib3/connectionpool.py", line 441, in _make_request
    httplib_response = conn.getresponse()
  File "/usr/lib/python3.10/http/client.py", line 1375, in getresponse
    response.begin()
  File "/usr/lib/python3.10/http/client.py", line 318, in begin
    version, status, reason = self._read_status()
  File "/usr/lib/python3.10/http/client.py", line 279, in _read_status
    line = str(self.fp.readline(_MAXLINE + 1), "iso-8859-1")
  File "/usr/lib/python3.10/socket.py", line 705, in readinto
    return self._sock.recv_into(b)
  File "/usr/lib/python3.10/ssl.py", line 1303, in recv_into
    return self.read(nbytes, buffer)
  File "/usr/lib/python3.10/ssl.py", line 1159, in read
    return self._sslobj.read(len, buffer)
TimeoutError: The read operation timed out

During handling of the above exception, another exception occurred:

Traceback (most recent call last):
  File "/usr/lib/python3/dist-packages/requests/adapters.py", line 439, in send
    resp = conn.urlopen(
  File "/usr/lib/python3/dist-packages/urllib3/connectionpool.py", line 756, in urlopen
    retries = retries.increment(
  File "/usr/lib/python3/dist-packages/urllib3/util/retry.py", line 534, in increment
    raise six.reraise(type(error), error, _stacktrace)
  File "/usr/lib/python3/dist-packages/six.py", line 719, in reraise
    raise value
  File "/usr/lib/python3/dist-packages/urllib3/connectionpool.py", line 700, in urlopen
    httplib_response = self._make_request(
  File "/usr/lib/python3/dist-packages/urllib3/connectionpool.py", line 448, in _make_request
    self._raise_timeout(err=e, url=url, timeout_value=read_timeout)
  File "/usr/lib/python3/dist-packages/urllib3/connectionpool.py", line 337, in _raise_timeout
    raise ReadTimeoutError(
urllib3.exceptions.ReadTimeoutError: HTTPSConnectionPool(host='api.telegram.org', port=443): Read timed out. (read timeout=10)

During handling of the above exception, another exception occurred:

Traceback (most recent call last):
  File "/usr/local/lib/python3.10/dist-packages/telebot/__init__.py", line 1110, in infinity_polling
    self.polling(non_stop=True, timeout=timeout, long_polling_timeout=long_polling_timeout,
  File "/usr/local/lib/python3.10/dist-packages/telebot/__init__.py", line 1198, in polling
    self.__threaded_polling(non_stop=non_stop, interval=interval, timeout=timeout, long_polling_timeout=long_polling_timeout,
  File "/usr/local/lib/python3.10/dist-packages/telebot/__init__.py", line 1273, in __threaded_polling
    raise e
  File "/usr/local/lib/python3.10/dist-packages/telebot/__init__.py", line 1234, in __threaded_polling
    polling_thread.raise_exceptions()
  File "/usr/local/lib/python3.10/dist-packages/telebot/util.py", line 111, in raise_exceptions
    raise self.exception_info
  File "/usr/local/lib/python3.10/dist-packages/telebot/util.py", line 93, in run
    task(*args, **kwargs)
  File "/usr/local/lib/python3.10/dist-packages/telebot/__init__.py", line 688, in __retrieve_updates
    updates = self.get_updates(offset=(self.last_update_id + 1),
  File "/usr/local/lib/python3.10/dist-packages/telebot/__init__.py", line 660, in get_updates
    json_updates = apihelper.get_updates(
  File "/usr/local/lib/python3.10/dist-packages/telebot/apihelper.py", line 332, in get_updates
    return _make_request(token, method_url, params=payload)
  File "/usr/local/lib/python3.10/dist-packages/telebot/apihelper.py", line 162, in _make_request
    result = _get_req_session().request(
  File "/usr/lib/python3/dist-packages/requests/sessions.py", line 544, in request
    resp = self.send(prep, **send_kwargs)
  File "/usr/lib/python3/dist-packages/requests/sessions.py", line 657, in send
    r = adapter.send(request, **kwargs)
  File "/usr/lib/python3/dist-packages/requests/adapters.py", line 529, in send
    raise ReadTimeout(e, request=request)
requests.exceptions.ReadTimeout: HTTPSConnectionPool(host='api.telegram.org', port=443): Read timed out. (read timeout=10)
"
2025-02-11 11:22:48,547 (__init__.py:1115 MainThread) ERROR - TeleBot: "Infinity polling exception: ('Connection aborted.', RemoteDisconnected('Remote end closed connection without response'))"
2025-02-11 11:22:48,548 (__init__.py:1117 MainThread) ERROR - TeleBot: "Exception traceback:
Traceback (most recent call last):
  File "/usr/lib/python3/dist-packages/urllib3/connectionpool.py", line 700, in urlopen
    httplib_response = self._make_request(
  File "/usr/lib/python3/dist-packages/urllib3/connectionpool.py", line 446, in _make_request
    six.raise_from(e, None)
  File "<string>", line 3, in raise_from
  File "/usr/lib/python3/dist-packages/urllib3/connectionpool.py", line 441, in _make_request
    httplib_response = conn.getresponse()
  File "/usr/lib/python3.10/http/client.py", line 1375, in getresponse
    response.begin()
  File "/usr/lib/python3.10/http/client.py", line 318, in begin
    version, status, reason = self._read_status()
  File "/usr/lib/python3.10/http/client.py", line 287, in _read_status
    raise RemoteDisconnected("Remote end closed connection without"
http.client.RemoteDisconnected: Remote end closed connection without response

During handling of the above exception, another exception occurred:

Traceback (most recent call last):
  File "/usr/lib/python3/dist-packages/requests/adapters.py", line 439, in send
    resp = conn.urlopen(
  File "/usr/lib/python3/dist-packages/urllib3/connectionpool.py", line 756, in urlopen
    retries = retries.increment(
  File "/usr/lib/python3/dist-packages/urllib3/util/retry.py", line 534, in increment
    raise six.reraise(type(error), error, _stacktrace)
  File "/usr/lib/python3/dist-packages/six.py", line 718, in reraise
    raise value.with_traceback(tb)
  File "/usr/lib/python3/dist-packages/urllib3/connectionpool.py", line 700, in urlopen
    httplib_response = self._make_request(
  File "/usr/lib/python3/dist-packages/urllib3/connectionpool.py", line 446, in _make_request
    six.raise_from(e, None)
  File "<string>", line 3, in raise_from
  File "/usr/lib/python3/dist-packages/urllib3/connectionpool.py", line 441, in _make_request
    httplib_response = conn.getresponse()
  File "/usr/lib/python3.10/http/client.py", line 1375, in getresponse
    response.begin()
  File "/usr/lib/python3.10/http/client.py", line 318, in begin
    version, status, reason = self._read_status()
  File "/usr/lib/python3.10/http/client.py", line 287, in _read_status
    raise RemoteDisconnected("Remote end closed connection without"
urllib3.exceptions.ProtocolError: ('Connection aborted.', RemoteDisconnected('Remote end closed connection without response'))

During handling of the above exception, another exception occurred:

Traceback (most recent call last):
  File "/usr/local/lib/python3.10/dist-packages/telebot/__init__.py", line 1110, in infinity_polling
    self.polling(non_stop=True, timeout=timeout, long_polling_timeout=long_polling_timeout,
  File "/usr/local/lib/python3.10/dist-packages/telebot/__init__.py", line 1198, in polling
    self.__threaded_polling(non_stop=non_stop, interval=interval, timeout=timeout, long_polling_timeout=long_polling_timeout,
  File "/usr/local/lib/python3.10/dist-packages/telebot/__init__.py", line 1273, in __threaded_polling
    raise e
  File "/usr/local/lib/python3.10/dist-packages/telebot/__init__.py", line 1234, in __threaded_polling
    polling_thread.raise_exceptions()
  File "/usr/local/lib/python3.10/dist-packages/telebot/util.py", line 111, in raise_exceptions
    raise self.exception_info
  File "/usr/local/lib/python3.10/dist-packages/telebot/util.py", line 93, in run
    task(*args, **kwargs)
  File "/usr/local/lib/python3.10/dist-packages/telebot/__init__.py", line 688, in __retrieve_updates
    updates = self.get_updates(offset=(self.last_update_id + 1),
  File "/usr/local/lib/python3.10/dist-packages/telebot/__init__.py", line 660, in get_updates
    json_updates = apihelper.get_updates(
  File "/usr/local/lib/python3.10/dist-packages/telebot/apihelper.py", line 332, in get_updates
    return _make_request(token, method_url, params=payload)
  File "/usr/local/lib/python3.10/dist-packages/telebot/apihelper.py", line 162, in _make_request
    result = _get_req_session().request(
  File "/usr/lib/python3/dist-packages/requests/sessions.py", line 544, in request
    resp = self.send(prep, **send_kwargs)
  File "/usr/lib/python3/dist-packages/requests/sessions.py", line 657, in send
    r = adapter.send(request, **kwargs)
  File "/usr/lib/python3/dist-packages/requests/adapters.py", line 498, in send
    raise ConnectionError(err, request=request)
requests.exceptions.ConnectionError: ('Connection aborted.', RemoteDisconnected('Remote end closed connection without response'))
"
2025-02-14 00:08:31,374 (__init__.py:1241 MainThread) ERROR - TeleBot: "Threaded polling exception: A request to the Telegram API was unsuccessful. Error code: 429. Description: Too Many Requests: retry after 5"
2025-02-14 00:08:31,375 (__init__.py:1243 MainThread) ERROR - TeleBot: "Exception traceback:
Traceback (most recent call last):
  File "/usr/local/lib/python3.10/dist-packages/telebot/__init__.py", line 1234, in __threaded_polling
    polling_thread.raise_exceptions()
  File "/usr/local/lib/python3.10/dist-packages/telebot/util.py", line 111, in raise_exceptions
    raise self.exception_info
  File "/usr/local/lib/python3.10/dist-packages/telebot/util.py", line 93, in run
    task(*args, **kwargs)
  File "/usr/local/lib/python3.10/dist-packages/telebot/__init__.py", line 688, in __retrieve_updates
    updates = self.get_updates(offset=(self.last_update_id + 1),
  File "/usr/local/lib/python3.10/dist-packages/telebot/__init__.py", line 660, in get_updates
    json_updates = apihelper.get_updates(
  File "/usr/local/lib/python3.10/dist-packages/telebot/apihelper.py", line 332, in get_updates
    return _make_request(token, method_url, params=payload)
  File "/usr/local/lib/python3.10/dist-packages/telebot/apihelper.py", line 168, in _make_request
    json_result = _check_result(method_name, result)
  File "/usr/local/lib/python3.10/dist-packages/telebot/apihelper.py", line 195, in _check_result
    raise ApiTelegramException(method_name, result, result_json)
telebot.apihelper.ApiTelegramException: A request to the Telegram API was unsuccessful. Error code: 429. Description: Too Many Requests: retry after 5
"
2025-02-14 00:08:31,679 (__init__.py:1241 MainThread) ERROR - TeleBot: "Threaded polling exception: A request to the Telegram API was unsuccessful. Error code: 429. Description: Too Many Requests: retry after 5"
2025-02-14 00:08:31,680 (__init__.py:1243 MainThread) ERROR - TeleBot: "Exception traceback:
Traceback (most recent call last):
  File "/usr/local/lib/python3.10/dist-packages/telebot/__init__.py", line 1234, in __threaded_polling
    polling_thread.raise_exceptions()
  File "/usr/local/lib/python3.10/dist-packages/telebot/util.py", line 111, in raise_exceptions
    raise self.exception_info
  File "/usr/local/lib/python3.10/dist-packages/telebot/util.py", line 93, in run
    task(*args, **kwargs)
  File "/usr/local/lib/python3.10/dist-packages/telebot/__init__.py", line 688, in __retrieve_updates
    updates = self.get_updates(offset=(self.last_update_id + 1),
  File "/usr/local/lib/python3.10/dist-packages/telebot/__init__.py", line 660, in get_updates
    json_updates = apihelper.get_updates(
  File "/usr/local/lib/python3.10/dist-packages/telebot/apihelper.py", line 332, in get_updates
    return _make_request(token, method_url, params=payload)
  File "/usr/local/lib/python3.10/dist-packages/telebot/apihelper.py", line 168, in _make_request
    json_result = _check_result(method_name, result)
  File "/usr/local/lib/python3.10/dist-packages/telebot/apihelper.py", line 195, in _check_result
    raise ApiTelegramException(method_name, result, result_json)
telebot.apihelper.ApiTelegramException: A request to the Telegram API was unsuccessful. Error code: 429. Description: Too Many Requests: retry after 5
"
2025-02-14 00:08:32,233 (__init__.py:1241 MainThread) ERROR - TeleBot: "Threaded polling exception: A request to the Telegram API was unsuccessful. Error code: 429. Description: Too Many Requests: retry after 5"
2025-02-14 00:08:32,234 (__init__.py:1243 MainThread) ERROR - TeleBot: "Exception traceback:
Traceback (most recent call last):
  File "/usr/local/lib/python3.10/dist-packages/telebot/__init__.py", line 1234, in __threaded_polling
    polling_thread.raise_exceptions()
  File "/usr/local/lib/python3.10/dist-packages/telebot/util.py", line 111, in raise_exceptions
    raise self.exception_info
  File "/usr/local/lib/python3.10/dist-packages/telebot/util.py", line 93, in run
    task(*args, **kwargs)
  File "/usr/local/lib/python3.10/dist-packages/telebot/__init__.py", line 688, in __retrieve_updates
    updates = self.get_updates(offset=(self.last_update_id + 1),
  File "/usr/local/lib/python3.10/dist-packages/telebot/__init__.py", line 660, in get_updates
    json_updates = apihelper.get_updates(
  File "/usr/local/lib/python3.10/dist-packages/telebot/apihelper.py", line 332, in get_updates
    return _make_request(token, method_url, params=payload)
  File "/usr/local/lib/python3.10/dist-packages/telebot/apihelper.py", line 168, in _make_request
    json_result = _check_result(method_name, result)
  File "/usr/local/lib/python3.10/dist-packages/telebot/apihelper.py", line 195, in _check_result
    raise ApiTelegramException(method_name, result, result_json)
telebot.apihelper.ApiTelegramException: A request to the Telegram API was unsuccessful. Error code: 429. Description: Too Many Requests: retry after 5
"
2025-02-14 00:08:33,286 (__init__.py:1241 MainThread) ERROR - TeleBot: "Threaded polling exception: A request to the Telegram API was unsuccessful. Error code: 429. Description: Too Many Requests: retry after 5"
2025-02-14 00:08:33,287 (__init__.py:1243 MainThread) ERROR - TeleBot: "Exception traceback:
Traceback (most recent call last):
  File "/usr/local/lib/python3.10/dist-packages/telebot/__init__.py", line 1234, in __threaded_polling
    polling_thread.raise_exceptions()
  File "/usr/local/lib/python3.10/dist-packages/telebot/util.py", line 111, in raise_exceptions
    raise self.exception_info
  File "/usr/local/lib/python3.10/dist-packages/telebot/util.py", line 93, in run
    task(*args, **kwargs)
  File "/usr/local/lib/python3.10/dist-packages/telebot/__init__.py", line 688, in __retrieve_updates
    updates = self.get_updates(offset=(self.last_update_id + 1),
  File "/usr/local/lib/python3.10/dist-packages/telebot/__init__.py", line 660, in get_updates
    json_updates = apihelper.get_updates(
  File "/usr/local/lib/python3.10/dist-packages/telebot/apihelper.py", line 332, in get_updates
    return _make_request(token, method_url, params=payload)
  File "/usr/local/lib/python3.10/dist-packages/telebot/apihelper.py", line 168, in _make_request
    json_result = _check_result(method_name, result)
  File "/usr/local/lib/python3.10/dist-packages/telebot/apihelper.py", line 195, in _check_result
    raise ApiTelegramException(method_name, result, result_json)
telebot.apihelper.ApiTelegramException: A request to the Telegram API was unsuccessful. Error code: 429. Description: Too Many Requests: retry after 5
"
2025-02-14 00:08:37,504 (__init__.py:1241 MainThread) ERROR - TeleBot: "Threaded polling exception: A request to the Telegram API was unsuccessful. Error code: 502. Description: Bad Gateway"
2025-02-14 00:08:37,505 (__init__.py:1243 MainThread) ERROR - TeleBot: "Exception traceback:
Traceback (most recent call last):
  File "/usr/local/lib/python3.10/dist-packages/telebot/__init__.py", line 1234, in __threaded_polling
    polling_thread.raise_exceptions()
  File "/usr/local/lib/python3.10/dist-packages/telebot/util.py", line 111, in raise_exceptions
    raise self.exception_info
  File "/usr/local/lib/python3.10/dist-packages/telebot/util.py", line 93, in run
    task(*args, **kwargs)
  File "/usr/local/lib/python3.10/dist-packages/telebot/__init__.py", line 688, in __retrieve_updates
    updates = self.get_updates(offset=(self.last_update_id + 1),
  File "/usr/local/lib/python3.10/dist-packages/telebot/__init__.py", line 660, in get_updates
    json_updates = apihelper.get_updates(
  File "/usr/local/lib/python3.10/dist-packages/telebot/apihelper.py", line 332, in get_updates
    return _make_request(token, method_url, params=payload)
  File "/usr/local/lib/python3.10/dist-packages/telebot/apihelper.py", line 168, in _make_request
    json_result = _check_result(method_name, result)
  File "/usr/local/lib/python3.10/dist-packages/telebot/apihelper.py", line 195, in _check_result
    raise ApiTelegramException(method_name, result, result_json)
telebot.apihelper.ApiTelegramException: A request to the Telegram API was unsuccessful. Error code: 502. Description: Bad Gateway
"
2025-02-14 00:08:51,526 (__init__.py:1115 MainThread) ERROR - TeleBot: "Infinity polling exception: HTTPSConnectionPool(host='api.telegram.org', port=443): Read timed out. (read timeout=10)"
2025-02-14 00:08:51,527 (__init__.py:1117 MainThread) ERROR - TeleBot: "Exception traceback:
Traceback (most recent call last):
  File "/usr/lib/python3/dist-packages/urllib3/connectionpool.py", line 446, in _make_request
    six.raise_from(e, None)
  File "<string>", line 3, in raise_from
  File "/usr/lib/python3/dist-packages/urllib3/connectionpool.py", line 441, in _make_request
    httplib_response = conn.getresponse()
  File "/usr/lib/python3.10/http/client.py", line 1375, in getresponse
    response.begin()
  File "/usr/lib/python3.10/http/client.py", line 318, in begin
    version, status, reason = self._read_status()
  File "/usr/lib/python3.10/http/client.py", line 279, in _read_status
    line = str(self.fp.readline(_MAXLINE + 1), "iso-8859-1")
  File "/usr/lib/python3.10/socket.py", line 705, in readinto
    return self._sock.recv_into(b)
  File "/usr/lib/python3.10/ssl.py", line 1303, in recv_into
    return self.read(nbytes, buffer)
  File "/usr/lib/python3.10/ssl.py", line 1159, in read
    return self._sslobj.read(len, buffer)
TimeoutError: The read operation timed out

During handling of the above exception, another exception occurred:

Traceback (most recent call last):
  File "/usr/lib/python3/dist-packages/requests/adapters.py", line 439, in send
    resp = conn.urlopen(
  File "/usr/lib/python3/dist-packages/urllib3/connectionpool.py", line 756, in urlopen
    retries = retries.increment(
  File "/usr/lib/python3/dist-packages/urllib3/util/retry.py", line 534, in increment
    raise six.reraise(type(error), error, _stacktrace)
  File "/usr/lib/python3/dist-packages/six.py", line 719, in reraise
    raise value
  File "/usr/lib/python3/dist-packages/urllib3/connectionpool.py", line 700, in urlopen
    httplib_response = self._make_request(
  File "/usr/lib/python3/dist-packages/urllib3/connectionpool.py", line 448, in _make_request
    self._raise_timeout(err=e, url=url, timeout_value=read_timeout)
  File "/usr/lib/python3/dist-packages/urllib3/connectionpool.py", line 337, in _raise_timeout
    raise ReadTimeoutError(
urllib3.exceptions.ReadTimeoutError: HTTPSConnectionPool(host='api.telegram.org', port=443): Read timed out. (read timeout=10)

During handling of the above exception, another exception occurred:

Traceback (most recent call last):
  File "/usr/local/lib/python3.10/dist-packages/telebot/__init__.py", line 1110, in infinity_polling
    self.polling(non_stop=True, timeout=timeout, long_polling_timeout=long_polling_timeout,
  File "/usr/local/lib/python3.10/dist-packages/telebot/__init__.py", line 1198, in polling
    self.__threaded_polling(non_stop=non_stop, interval=interval, timeout=timeout, long_polling_timeout=long_polling_timeout,
  File "/usr/local/lib/python3.10/dist-packages/telebot/__init__.py", line 1273, in __threaded_polling
    raise e
  File "/usr/local/lib/python3.10/dist-packages/telebot/__init__.py", line 1234, in __threaded_polling
    polling_thread.raise_exceptions()
  File "/usr/local/lib/python3.10/dist-packages/telebot/util.py", line 111, in raise_exceptions
    raise self.exception_info
  File "/usr/local/lib/python3.10/dist-packages/telebot/util.py", line 93, in run
    task(*args, **kwargs)
  File "/usr/local/lib/python3.10/dist-packages/telebot/__init__.py", line 688, in __retrieve_updates
    updates = self.get_updates(offset=(self.last_update_id + 1),
  File "/usr/local/lib/python3.10/dist-packages/telebot/__init__.py", line 660, in get_updates
    json_updates = apihelper.get_updates(
  File "/usr/local/lib/python3.10/dist-packages/telebot/apihelper.py", line 332, in get_updates
    return _make_request(token, method_url, params=payload)
  File "/usr/local/lib/python3.10/dist-packages/telebot/apihelper.py", line 162, in _make_request
    result = _get_req_session().request(
  File "/usr/lib/python3/dist-packages/requests/sessions.py", line 544, in request
    resp = self.send(prep, **send_kwargs)
  File "/usr/lib/python3/dist-packages/requests/sessions.py", line 657, in send
    r = adapter.send(request, **kwargs)
  File "/usr/lib/python3/dist-packages/requests/adapters.py", line 529, in send
    raise ReadTimeout(e, request=request)
requests.exceptions.ReadTimeout: HTTPSConnectionPool(host='api.telegram.org', port=443): Read timed out. (read timeout=10)
"
2025-02-14 00:09:04,713 (__init__.py:1115 MainThread) ERROR - TeleBot: "Infinity polling exception: HTTPSConnectionPool(host='api.telegram.org', port=443): Read timed out. (read timeout=10)"
2025-02-14 00:09:04,714 (__init__.py:1117 MainThread) ERROR - TeleBot: "Exception traceback:
Traceback (most recent call last):
  File "/usr/lib/python3/dist-packages/urllib3/connectionpool.py", line 446, in _make_request
    six.raise_from(e, None)
  File "<string>", line 3, in raise_from
  File "/usr/lib/python3/dist-packages/urllib3/connectionpool.py", line 441, in _make_request
    httplib_response = conn.getresponse()
  File "/usr/lib/python3.10/http/client.py", line 1375, in getresponse
    response.begin()
  File "/usr/lib/python3.10/http/client.py", line 318, in begin
    version, status, reason = self._read_status()
  File "/usr/lib/python3.10/http/client.py", line 279, in _read_status
    line = str(self.fp.readline(_MAXLINE + 1), "iso-8859-1")
  File "/usr/lib/python3.10/socket.py", line 705, in readinto
    return self._sock.recv_into(b)
  File "/usr/lib/python3.10/ssl.py", line 1303, in recv_into
    return self.read(nbytes, buffer)
  File "/usr/lib/python3.10/ssl.py", line 1159, in read
    return self._sslobj.read(len, buffer)
TimeoutError: The read operation timed out

During handling of the above exception, another exception occurred:

Traceback (most recent call last):
  File "/usr/lib/python3/dist-packages/requests/adapters.py", line 439, in send
    resp = conn.urlopen(
  File "/usr/lib/python3/dist-packages/urllib3/connectionpool.py", line 756, in urlopen
    retries = retries.increment(
  File "/usr/lib/python3/dist-packages/urllib3/util/retry.py", line 534, in increment
    raise six.reraise(type(error), error, _stacktrace)
  File "/usr/lib/python3/dist-packages/six.py", line 719, in reraise
    raise value
  File "/usr/lib/python3/dist-packages/urllib3/connectionpool.py", line 700, in urlopen
    httplib_response = self._make_request(
  File "/usr/lib/python3/dist-packages/urllib3/connectionpool.py", line 448, in _make_request
    self._raise_timeout(err=e, url=url, timeout_value=read_timeout)
  File "/usr/lib/python3/dist-packages/urllib3/connectionpool.py", line 337, in _raise_timeout
    raise ReadTimeoutError(
urllib3.exceptions.ReadTimeoutError: HTTPSConnectionPool(host='api.telegram.org', port=443): Read timed out. (read timeout=10)

During handling of the above exception, another exception occurred:

Traceback (most recent call last):
  File "/usr/local/lib/python3.10/dist-packages/telebot/__init__.py", line 1110, in infinity_polling
    self.polling(non_stop=True, timeout=timeout, long_polling_timeout=long_polling_timeout,
  File "/usr/local/lib/python3.10/dist-packages/telebot/__init__.py", line 1198, in polling
    self.__threaded_polling(non_stop=non_stop, interval=interval, timeout=timeout, long_polling_timeout=long_polling_timeout,
  File "/usr/local/lib/python3.10/dist-packages/telebot/__init__.py", line 1273, in __threaded_polling
    raise e
  File "/usr/local/lib/python3.10/dist-packages/telebot/__init__.py", line 1234, in __threaded_polling
    polling_thread.raise_exceptions()
  File "/usr/local/lib/python3.10/dist-packages/telebot/util.py", line 111, in raise_exceptions
    raise self.exception_info
  File "/usr/local/lib/python3.10/dist-packages/telebot/util.py", line 93, in run
    task(*args, **kwargs)
  File "/usr/local/lib/python3.10/dist-packages/telebot/__init__.py", line 688, in __retrieve_updates
    updates = self.get_updates(offset=(self.last_update_id + 1),
  File "/usr/local/lib/python3.10/dist-packages/telebot/__init__.py", line 660, in get_updates
    json_updates = apihelper.get_updates(
  File "/usr/local/lib/python3.10/dist-packages/telebot/apihelper.py", line 332, in get_updates
    return _make_request(token, method_url, params=payload)
  File "/usr/local/lib/python3.10/dist-packages/telebot/apihelper.py", line 162, in _make_request
    result = _get_req_session().request(
  File "/usr/lib/python3/dist-packages/requests/sessions.py", line 544, in request
    resp = self.send(prep, **send_kwargs)
  File "/usr/lib/python3/dist-packages/requests/sessions.py", line 657, in send
    r = adapter.send(request, **kwargs)
  File "/usr/lib/python3/dist-packages/requests/adapters.py", line 529, in send
    raise ReadTimeout(e, request=request)
requests.exceptions.ReadTimeout: HTTPSConnectionPool(host='api.telegram.org', port=443): Read timed out. (read timeout=10)
"
2025-02-14 08:50:22,220 (__init__.py:1115 MainThread) ERROR - TeleBot: "Infinity polling exception: HTTPSConnectionPool(host='api.telegram.org', port=443): Read timed out. (read timeout=10)"
2025-02-14 08:50:22,221 (__init__.py:1117 MainThread) ERROR - TeleBot: "Exception traceback:
Traceback (most recent call last):
  File "/usr/lib/python3/dist-packages/urllib3/connectionpool.py", line 446, in _make_request
    six.raise_from(e, None)
  File "<string>", line 3, in raise_from
  File "/usr/lib/python3/dist-packages/urllib3/connectionpool.py", line 441, in _make_request
    httplib_response = conn.getresponse()
  File "/usr/lib/python3.10/http/client.py", line 1375, in getresponse
    response.begin()
  File "/usr/lib/python3.10/http/client.py", line 318, in begin
    version, status, reason = self._read_status()
  File "/usr/lib/python3.10/http/client.py", line 279, in _read_status
    line = str(self.fp.readline(_MAXLINE + 1), "iso-8859-1")
  File "/usr/lib/python3.10/socket.py", line 705, in readinto
    return self._sock.recv_into(b)
  File "/usr/lib/python3.10/ssl.py", line 1303, in recv_into
    return self.read(nbytes, buffer)
  File "/usr/lib/python3.10/ssl.py", line 1159, in read
    return self._sslobj.read(len, buffer)
TimeoutError: The read operation timed out

During handling of the above exception, another exception occurred:

Traceback (most recent call last):
  File "/usr/lib/python3/dist-packages/requests/adapters.py", line 439, in send
    resp = conn.urlopen(
  File "/usr/lib/python3/dist-packages/urllib3/connectionpool.py", line 756, in urlopen
    retries = retries.increment(
  File "/usr/lib/python3/dist-packages/urllib3/util/retry.py", line 534, in increment
    raise six.reraise(type(error), error, _stacktrace)
  File "/usr/lib/python3/dist-packages/six.py", line 719, in reraise
    raise value
  File "/usr/lib/python3/dist-packages/urllib3/connectionpool.py", line 700, in urlopen
    httplib_response = self._make_request(
  File "/usr/lib/python3/dist-packages/urllib3/connectionpool.py", line 448, in _make_request
    self._raise_timeout(err=e, url=url, timeout_value=read_timeout)
  File "/usr/lib/python3/dist-packages/urllib3/connectionpool.py", line 337, in _raise_timeout
    raise ReadTimeoutError(
urllib3.exceptions.ReadTimeoutError: HTTPSConnectionPool(host='api.telegram.org', port=443): Read timed out. (read timeout=10)

During handling of the above exception, another exception occurred:

Traceback (most recent call last):
  File "/usr/local/lib/python3.10/dist-packages/telebot/__init__.py", line 1110, in infinity_polling
    self.polling(non_stop=True, timeout=timeout, long_polling_timeout=long_polling_timeout,
  File "/usr/local/lib/python3.10/dist-packages/telebot/__init__.py", line 1198, in polling
    self.__threaded_polling(non_stop=non_stop, interval=interval, timeout=timeout, long_polling_timeout=long_polling_timeout,
  File "/usr/local/lib/python3.10/dist-packages/telebot/__init__.py", line 1273, in __threaded_polling
    raise e
  File "/usr/local/lib/python3.10/dist-packages/telebot/__init__.py", line 1234, in __threaded_polling
    polling_thread.raise_exceptions()
  File "/usr/local/lib/python3.10/dist-packages/telebot/util.py", line 111, in raise_exceptions
    raise self.exception_info
  File "/usr/local/lib/python3.10/dist-packages/telebot/util.py", line 93, in run
    task(*args, **kwargs)
  File "/usr/local/lib/python3.10/dist-packages/telebot/__init__.py", line 688, in __retrieve_updates
    updates = self.get_updates(offset=(self.last_update_id + 1),
  File "/usr/local/lib/python3.10/dist-packages/telebot/__init__.py", line 660, in get_updates
    json_updates = apihelper.get_updates(
  File "/usr/local/lib/python3.10/dist-packages/telebot/apihelper.py", line 332, in get_updates
    return _make_request(token, method_url, params=payload)
  File "/usr/local/lib/python3.10/dist-packages/telebot/apihelper.py", line 162, in _make_request
    result = _get_req_session().request(
  File "/usr/lib/python3/dist-packages/requests/sessions.py", line 544, in request
    resp = self.send(prep, **send_kwargs)
  File "/usr/lib/python3/dist-packages/requests/sessions.py", line 657, in send
    r = adapter.send(request, **kwargs)
  File "/usr/lib/python3/dist-packages/requests/adapters.py", line 529, in send
    raise ReadTimeout(e, request=request)
requests.exceptions.ReadTimeout: HTTPSConnectionPool(host='api.telegram.org', port=443): Read timed out. (read timeout=10)
"
2025-02-18 09:58:18,830 (__init__.py:1115 MainThread) ERROR - TeleBot: "Infinity polling exception: ('Connection aborted.', RemoteDisconnected('Remote end closed connection without response'))"
2025-02-18 09:58:18,832 (__init__.py:1117 MainThread) ERROR - TeleBot: "Exception traceback:
Traceback (most recent call last):
  File "/usr/lib/python3/dist-packages/urllib3/connectionpool.py", line 700, in urlopen
    httplib_response = self._make_request(
  File "/usr/lib/python3/dist-packages/urllib3/connectionpool.py", line 446, in _make_request
    six.raise_from(e, None)
  File "<string>", line 3, in raise_from
  File "/usr/lib/python3/dist-packages/urllib3/connectionpool.py", line 441, in _make_request
    httplib_response = conn.getresponse()
  File "/usr/lib/python3.10/http/client.py", line 1375, in getresponse
    response.begin()
  File "/usr/lib/python3.10/http/client.py", line 318, in begin
    version, status, reason = self._read_status()
  File "/usr/lib/python3.10/http/client.py", line 287, in _read_status
    raise RemoteDisconnected("Remote end closed connection without"
http.client.RemoteDisconnected: Remote end closed connection without response

During handling of the above exception, another exception occurred:

Traceback (most recent call last):
  File "/usr/lib/python3/dist-packages/requests/adapters.py", line 439, in send
    resp = conn.urlopen(
  File "/usr/lib/python3/dist-packages/urllib3/connectionpool.py", line 756, in urlopen
    retries = retries.increment(
  File "/usr/lib/python3/dist-packages/urllib3/util/retry.py", line 534, in increment
    raise six.reraise(type(error), error, _stacktrace)
  File "/usr/lib/python3/dist-packages/six.py", line 718, in reraise
    raise value.with_traceback(tb)
  File "/usr/lib/python3/dist-packages/urllib3/connectionpool.py", line 700, in urlopen
    httplib_response = self._make_request(
  File "/usr/lib/python3/dist-packages/urllib3/connectionpool.py", line 446, in _make_request
    six.raise_from(e, None)
  File "<string>", line 3, in raise_from
  File "/usr/lib/python3/dist-packages/urllib3/connectionpool.py", line 441, in _make_request
    httplib_response = conn.getresponse()
  File "/usr/lib/python3.10/http/client.py", line 1375, in getresponse
    response.begin()
  File "/usr/lib/python3.10/http/client.py", line 318, in begin
    version, status, reason = self._read_status()
  File "/usr/lib/python3.10/http/client.py", line 287, in _read_status
    raise RemoteDisconnected("Remote end closed connection without"
urllib3.exceptions.ProtocolError: ('Connection aborted.', RemoteDisconnected('Remote end closed connection without response'))

During handling of the above exception, another exception occurred:

Traceback (most recent call last):
  File "/usr/local/lib/python3.10/dist-packages/telebot/__init__.py", line 1110, in infinity_polling
    self.polling(non_stop=True, timeout=timeout, long_polling_timeout=long_polling_timeout,
  File "/usr/local/lib/python3.10/dist-packages/telebot/__init__.py", line 1198, in polling
    self.__threaded_polling(non_stop=non_stop, interval=interval, timeout=timeout, long_polling_timeout=long_polling_timeout,
  File "/usr/local/lib/python3.10/dist-packages/telebot/__init__.py", line 1273, in __threaded_polling
    raise e
  File "/usr/local/lib/python3.10/dist-packages/telebot/__init__.py", line 1234, in __threaded_polling
    polling_thread.raise_exceptions()
  File "/usr/local/lib/python3.10/dist-packages/telebot/util.py", line 111, in raise_exceptions
    raise self.exception_info
  File "/usr/local/lib/python3.10/dist-packages/telebot/util.py", line 93, in run
    task(*args, **kwargs)
  File "/usr/local/lib/python3.10/dist-packages/telebot/__init__.py", line 688, in __retrieve_updates
    updates = self.get_updates(offset=(self.last_update_id + 1),
  File "/usr/local/lib/python3.10/dist-packages/telebot/__init__.py", line 660, in get_updates
    json_updates = apihelper.get_updates(
  File "/usr/local/lib/python3.10/dist-packages/telebot/apihelper.py", line 332, in get_updates
    return _make_request(token, method_url, params=payload)
  File "/usr/local/lib/python3.10/dist-packages/telebot/apihelper.py", line 162, in _make_request
    result = _get_req_session().request(
  File "/usr/lib/python3/dist-packages/requests/sessions.py", line 544, in request
    resp = self.send(prep, **send_kwargs)
  File "/usr/lib/python3/dist-packages/requests/sessions.py", line 657, in send
    r = adapter.send(request, **kwargs)
  File "/usr/lib/python3/dist-packages/requests/adapters.py", line 498, in send
    raise ConnectionError(err, request=request)
requests.exceptions.ConnectionError: ('Connection aborted.', RemoteDisconnected('Remote end closed connection without response'))
"
2025-02-18 18:18:36,763 (__init__.py:1115 MainThread) ERROR - TeleBot: "Infinity polling exception: ('Connection aborted.', RemoteDisconnected('Remote end closed connection without response'))"
2025-02-18 18:18:36,763 (__init__.py:1117 MainThread) ERROR - TeleBot: "Exception traceback:
Traceback (most recent call last):
  File "/usr/lib/python3/dist-packages/urllib3/connectionpool.py", line 700, in urlopen
    httplib_response = self._make_request(
  File "/usr/lib/python3/dist-packages/urllib3/connectionpool.py", line 446, in _make_request
    six.raise_from(e, None)
  File "<string>", line 3, in raise_from
  File "/usr/lib/python3/dist-packages/urllib3/connectionpool.py", line 441, in _make_request
    httplib_response = conn.getresponse()
  File "/usr/lib/python3.10/http/client.py", line 1375, in getresponse
    response.begin()
  File "/usr/lib/python3.10/http/client.py", line 318, in begin
    version, status, reason = self._read_status()
  File "/usr/lib/python3.10/http/client.py", line 287, in _read_status
    raise RemoteDisconnected("Remote end closed connection without"
http.client.RemoteDisconnected: Remote end closed connection without response

During handling of the above exception, another exception occurred:

Traceback (most recent call last):
  File "/usr/lib/python3/dist-packages/requests/adapters.py", line 439, in send
    resp = conn.urlopen(
  File "/usr/lib/python3/dist-packages/urllib3/connectionpool.py", line 756, in urlopen
    retries = retries.increment(
  File "/usr/lib/python3/dist-packages/urllib3/util/retry.py", line 534, in increment
    raise six.reraise(type(error), error, _stacktrace)
  File "/usr/lib/python3/dist-packages/six.py", line 718, in reraise
    raise value.with_traceback(tb)
  File "/usr/lib/python3/dist-packages/urllib3/connectionpool.py", line 700, in urlopen
    httplib_response = self._make_request(
  File "/usr/lib/python3/dist-packages/urllib3/connectionpool.py", line 446, in _make_request
    six.raise_from(e, None)
  File "<string>", line 3, in raise_from
  File "/usr/lib/python3/dist-packages/urllib3/connectionpool.py", line 441, in _make_request
    httplib_response = conn.getresponse()
  File "/usr/lib/python3.10/http/client.py", line 1375, in getresponse
    response.begin()
  File "/usr/lib/python3.10/http/client.py", line 318, in begin
    version, status, reason = self._read_status()
  File "/usr/lib/python3.10/http/client.py", line 287, in _read_status
    raise RemoteDisconnected("Remote end closed connection without"
urllib3.exceptions.ProtocolError: ('Connection aborted.', RemoteDisconnected('Remote end closed connection without response'))

During handling of the above exception, another exception occurred:

Traceback (most recent call last):
  File "/usr/local/lib/python3.10/dist-packages/telebot/__init__.py", line 1110, in infinity_polling
    self.polling(non_stop=True, timeout=timeout, long_polling_timeout=long_polling_timeout,
  File "/usr/local/lib/python3.10/dist-packages/telebot/__init__.py", line 1198, in polling
    self.__threaded_polling(non_stop=non_stop, interval=interval, timeout=timeout, long_polling_timeout=long_polling_timeout,
  File "/usr/local/lib/python3.10/dist-packages/telebot/__init__.py", line 1273, in __threaded_polling
    raise e
  File "/usr/local/lib/python3.10/dist-packages/telebot/__init__.py", line 1234, in __threaded_polling
    polling_thread.raise_exceptions()
  File "/usr/local/lib/python3.10/dist-packages/telebot/util.py", line 111, in raise_exceptions
    raise self.exception_info
  File "/usr/local/lib/python3.10/dist-packages/telebot/util.py", line 93, in run
    task(*args, **kwargs)
  File "/usr/local/lib/python3.10/dist-packages/telebot/__init__.py", line 688, in __retrieve_updates
    updates = self.get_updates(offset=(self.last_update_id + 1),
  File "/usr/local/lib/python3.10/dist-packages/telebot/__init__.py", line 660, in get_updates
    json_updates = apihelper.get_updates(
  File "/usr/local/lib/python3.10/dist-packages/telebot/apihelper.py", line 332, in get_updates
    return _make_request(token, method_url, params=payload)
  File "/usr/local/lib/python3.10/dist-packages/telebot/apihelper.py", line 162, in _make_request
    result = _get_req_session().request(
  File "/usr/lib/python3/dist-packages/requests/sessions.py", line 544, in request
    resp = self.send(prep, **send_kwargs)
  File "/usr/lib/python3/dist-packages/requests/sessions.py", line 657, in send
    r = adapter.send(request, **kwargs)
  File "/usr/lib/python3/dist-packages/requests/adapters.py", line 498, in send
    raise ConnectionError(err, request=request)
requests.exceptions.ConnectionError: ('Connection aborted.', RemoteDisconnected('Remote end closed connection without response'))
"
2025-02-21 05:25:38,811 (__init__.py:1115 MainThread) ERROR - TeleBot: "Infinity polling exception: HTTPSConnectionPool(host='api.telegram.org', port=443): Read timed out. (read timeout=10)"
2025-02-21 05:25:38,814 (__init__.py:1117 MainThread) ERROR - TeleBot: "Exception traceback:
Traceback (most recent call last):
  File "/usr/lib/python3/dist-packages/urllib3/connectionpool.py", line 446, in _make_request
    six.raise_from(e, None)
  File "<string>", line 3, in raise_from
  File "/usr/lib/python3/dist-packages/urllib3/connectionpool.py", line 441, in _make_request
    httplib_response = conn.getresponse()
  File "/usr/lib/python3.10/http/client.py", line 1375, in getresponse
    response.begin()
  File "/usr/lib/python3.10/http/client.py", line 318, in begin
    version, status, reason = self._read_status()
  File "/usr/lib/python3.10/http/client.py", line 279, in _read_status
    line = str(self.fp.readline(_MAXLINE + 1), "iso-8859-1")
  File "/usr/lib/python3.10/socket.py", line 705, in readinto
    return self._sock.recv_into(b)
  File "/usr/lib/python3.10/ssl.py", line 1303, in recv_into
    return self.read(nbytes, buffer)
  File "/usr/lib/python3.10/ssl.py", line 1159, in read
    return self._sslobj.read(len, buffer)
TimeoutError: The read operation timed out

During handling of the above exception, another exception occurred:

Traceback (most recent call last):
  File "/usr/lib/python3/dist-packages/requests/adapters.py", line 439, in send
    resp = conn.urlopen(
  File "/usr/lib/python3/dist-packages/urllib3/connectionpool.py", line 756, in urlopen
    retries = retries.increment(
  File "/usr/lib/python3/dist-packages/urllib3/util/retry.py", line 534, in increment
    raise six.reraise(type(error), error, _stacktrace)
  File "/usr/lib/python3/dist-packages/six.py", line 719, in reraise
    raise value
  File "/usr/lib/python3/dist-packages/urllib3/connectionpool.py", line 700, in urlopen
    httplib_response = self._make_request(
  File "/usr/lib/python3/dist-packages/urllib3/connectionpool.py", line 448, in _make_request
    self._raise_timeout(err=e, url=url, timeout_value=read_timeout)
  File "/usr/lib/python3/dist-packages/urllib3/connectionpool.py", line 337, in _raise_timeout
    raise ReadTimeoutError(
urllib3.exceptions.ReadTimeoutError: HTTPSConnectionPool(host='api.telegram.org', port=443): Read timed out. (read timeout=10)

During handling of the above exception, another exception occurred:

Traceback (most recent call last):
  File "/usr/local/lib/python3.10/dist-packages/telebot/__init__.py", line 1110, in infinity_polling
    self.polling(non_stop=True, timeout=timeout, long_polling_timeout=long_polling_timeout,
  File "/usr/local/lib/python3.10/dist-packages/telebot/__init__.py", line 1198, in polling
    self.__threaded_polling(non_stop=non_stop, interval=interval, timeout=timeout, long_polling_timeout=long_polling_timeout,
  File "/usr/local/lib/python3.10/dist-packages/telebot/__init__.py", line 1273, in __threaded_polling
    raise e
  File "/usr/local/lib/python3.10/dist-packages/telebot/__init__.py", line 1234, in __threaded_polling
    polling_thread.raise_exceptions()
  File "/usr/local/lib/python3.10/dist-packages/telebot/util.py", line 111, in raise_exceptions
    raise self.exception_info
  File "/usr/local/lib/python3.10/dist-packages/telebot/util.py", line 93, in run
    task(*args, **kwargs)
  File "/usr/local/lib/python3.10/dist-packages/telebot/__init__.py", line 688, in __retrieve_updates
    updates = self.get_updates(offset=(self.last_update_id + 1),
  File "/usr/local/lib/python3.10/dist-packages/telebot/__init__.py", line 660, in get_updates
    json_updates = apihelper.get_updates(
  File "/usr/local/lib/python3.10/dist-packages/telebot/apihelper.py", line 332, in get_updates
    return _make_request(token, method_url, params=payload)
  File "/usr/local/lib/python3.10/dist-packages/telebot/apihelper.py", line 162, in _make_request
    result = _get_req_session().request(
  File "/usr/lib/python3/dist-packages/requests/sessions.py", line 544, in request
    resp = self.send(prep, **send_kwargs)
  File "/usr/lib/python3/dist-packages/requests/sessions.py", line 657, in send
    r = adapter.send(request, **kwargs)
  File "/usr/lib/python3/dist-packages/requests/adapters.py", line 529, in send
    raise ReadTimeout(e, request=request)
requests.exceptions.ReadTimeout: HTTPSConnectionPool(host='api.telegram.org', port=443): Read timed out. (read timeout=10)
"
2025-02-21 09:04:01,720 (__init__.py:1115 MainThread) ERROR - TeleBot: "Infinity polling exception: HTTPSConnectionPool(host='api.telegram.org', port=443): Read timed out. (read timeout=10)"
2025-02-21 09:04:01,723 (__init__.py:1117 MainThread) ERROR - TeleBot: "Exception traceback:
Traceback (most recent call last):
  File "/usr/lib/python3/dist-packages/urllib3/connectionpool.py", line 446, in _make_request
    six.raise_from(e, None)
  File "<string>", line 3, in raise_from
  File "/usr/lib/python3/dist-packages/urllib3/connectionpool.py", line 441, in _make_request
    httplib_response = conn.getresponse()
  File "/usr/lib/python3.10/http/client.py", line 1375, in getresponse
    response.begin()
  File "/usr/lib/python3.10/http/client.py", line 318, in begin
    version, status, reason = self._read_status()
  File "/usr/lib/python3.10/http/client.py", line 279, in _read_status
    line = str(self.fp.readline(_MAXLINE + 1), "iso-8859-1")
  File "/usr/lib/python3.10/socket.py", line 705, in readinto
    return self._sock.recv_into(b)
  File "/usr/lib/python3.10/ssl.py", line 1303, in recv_into
    return self.read(nbytes, buffer)
  File "/usr/lib/python3.10/ssl.py", line 1159, in read
    return self._sslobj.read(len, buffer)
TimeoutError: The read operation timed out

During handling of the above exception, another exception occurred:

Traceback (most recent call last):
  File "/usr/lib/python3/dist-packages/requests/adapters.py", line 439, in send
    resp = conn.urlopen(
  File "/usr/lib/python3/dist-packages/urllib3/connectionpool.py", line 756, in urlopen
    retries = retries.increment(
  File "/usr/lib/python3/dist-packages/urllib3/util/retry.py", line 534, in increment
    raise six.reraise(type(error), error, _stacktrace)
  File "/usr/lib/python3/dist-packages/six.py", line 719, in reraise
    raise value
  File "/usr/lib/python3/dist-packages/urllib3/connectionpool.py", line 700, in urlopen
    httplib_response = self._make_request(
  File "/usr/lib/python3/dist-packages/urllib3/connectionpool.py", line 448, in _make_request
    self._raise_timeout(err=e, url=url, timeout_value=read_timeout)
  File "/usr/lib/python3/dist-packages/urllib3/connectionpool.py", line 337, in _raise_timeout
    raise ReadTimeoutError(
urllib3.exceptions.ReadTimeoutError: HTTPSConnectionPool(host='api.telegram.org', port=443): Read timed out. (read timeout=10)

During handling of the above exception, another exception occurred:

Traceback (most recent call last):
  File "/usr/local/lib/python3.10/dist-packages/telebot/__init__.py", line 1110, in infinity_polling
    self.polling(non_stop=True, timeout=timeout, long_polling_timeout=long_polling_timeout,
  File "/usr/local/lib/python3.10/dist-packages/telebot/__init__.py", line 1198, in polling
    self.__threaded_polling(non_stop=non_stop, interval=interval, timeout=timeout, long_polling_timeout=long_polling_timeout,
  File "/usr/local/lib/python3.10/dist-packages/telebot/__init__.py", line 1273, in __threaded_polling
    raise e
  File "/usr/local/lib/python3.10/dist-packages/telebot/__init__.py", line 1234, in __threaded_polling
    polling_thread.raise_exceptions()
  File "/usr/local/lib/python3.10/dist-packages/telebot/util.py", line 111, in raise_exceptions
    raise self.exception_info
  File "/usr/local/lib/python3.10/dist-packages/telebot/util.py", line 93, in run
    task(*args, **kwargs)
  File "/usr/local/lib/python3.10/dist-packages/telebot/__init__.py", line 688, in __retrieve_updates
    updates = self.get_updates(offset=(self.last_update_id + 1),
  File "/usr/local/lib/python3.10/dist-packages/telebot/__init__.py", line 660, in get_updates
    json_updates = apihelper.get_updates(
  File "/usr/local/lib/python3.10/dist-packages/telebot/apihelper.py", line 332, in get_updates
    return _make_request(token, method_url, params=payload)
  File "/usr/local/lib/python3.10/dist-packages/telebot/apihelper.py", line 162, in _make_request
    result = _get_req_session().request(
  File "/usr/lib/python3/dist-packages/requests/sessions.py", line 544, in request
    resp = self.send(prep, **send_kwargs)
  File "/usr/lib/python3/dist-packages/requests/sessions.py", line 657, in send
    r = adapter.send(request, **kwargs)
  File "/usr/lib/python3/dist-packages/requests/adapters.py", line 529, in send
    raise ReadTimeout(e, request=request)
requests.exceptions.ReadTimeout: HTTPSConnectionPool(host='api.telegram.org', port=443): Read timed out. (read timeout=10)
"
2025-02-21 11:09:40,821 (__init__.py:1115 MainThread) ERROR - TeleBot: "Infinity polling exception: ('Connection aborted.', RemoteDisconnected('Remote end closed connection without response'))"
2025-02-21 11:09:40,822 (__init__.py:1117 MainThread) ERROR - TeleBot: "Exception traceback:
Traceback (most recent call last):
  File "/usr/lib/python3/dist-packages/urllib3/connectionpool.py", line 700, in urlopen
    httplib_response = self._make_request(
  File "/usr/lib/python3/dist-packages/urllib3/connectionpool.py", line 446, in _make_request
    six.raise_from(e, None)
  File "<string>", line 3, in raise_from
  File "/usr/lib/python3/dist-packages/urllib3/connectionpool.py", line 441, in _make_request
    httplib_response = conn.getresponse()
  File "/usr/lib/python3.10/http/client.py", line 1375, in getresponse
    response.begin()
  File "/usr/lib/python3.10/http/client.py", line 318, in begin
    version, status, reason = self._read_status()
  File "/usr/lib/python3.10/http/client.py", line 287, in _read_status
    raise RemoteDisconnected("Remote end closed connection without"
http.client.RemoteDisconnected: Remote end closed connection without response

During handling of the above exception, another exception occurred:

Traceback (most recent call last):
  File "/usr/lib/python3/dist-packages/requests/adapters.py", line 439, in send
    resp = conn.urlopen(
  File "/usr/lib/python3/dist-packages/urllib3/connectionpool.py", line 756, in urlopen
    retries = retries.increment(
  File "/usr/lib/python3/dist-packages/urllib3/util/retry.py", line 534, in increment
    raise six.reraise(type(error), error, _stacktrace)
  File "/usr/lib/python3/dist-packages/six.py", line 718, in reraise
    raise value.with_traceback(tb)
  File "/usr/lib/python3/dist-packages/urllib3/connectionpool.py", line 700, in urlopen
    httplib_response = self._make_request(
  File "/usr/lib/python3/dist-packages/urllib3/connectionpool.py", line 446, in _make_request
    six.raise_from(e, None)
  File "<string>", line 3, in raise_from
  File "/usr/lib/python3/dist-packages/urllib3/connectionpool.py", line 441, in _make_request
    httplib_response = conn.getresponse()
  File "/usr/lib/python3.10/http/client.py", line 1375, in getresponse
    response.begin()
  File "/usr/lib/python3.10/http/client.py", line 318, in begin
    version, status, reason = self._read_status()
  File "/usr/lib/python3.10/http/client.py", line 287, in _read_status
    raise RemoteDisconnected("Remote end closed connection without"
urllib3.exceptions.ProtocolError: ('Connection aborted.', RemoteDisconnected('Remote end closed connection without response'))

During handling of the above exception, another exception occurred:

Traceback (most recent call last):
  File "/usr/local/lib/python3.10/dist-packages/telebot/__init__.py", line 1110, in infinity_polling
    self.polling(non_stop=True, timeout=timeout, long_polling_timeout=long_polling_timeout,
  File "/usr/local/lib/python3.10/dist-packages/telebot/__init__.py", line 1198, in polling
    self.__threaded_polling(non_stop=non_stop, interval=interval, timeout=timeout, long_polling_timeout=long_polling_timeout,
  File "/usr/local/lib/python3.10/dist-packages/telebot/__init__.py", line 1273, in __threaded_polling
    raise e
  File "/usr/local/lib/python3.10/dist-packages/telebot/__init__.py", line 1234, in __threaded_polling
    polling_thread.raise_exceptions()
  File "/usr/local/lib/python3.10/dist-packages/telebot/util.py", line 111, in raise_exceptions
    raise self.exception_info
  File "/usr/local/lib/python3.10/dist-packages/telebot/util.py", line 93, in run
    task(*args, **kwargs)
  File "/usr/local/lib/python3.10/dist-packages/telebot/__init__.py", line 688, in __retrieve_updates
    updates = self.get_updates(offset=(self.last_update_id + 1),
  File "/usr/local/lib/python3.10/dist-packages/telebot/__init__.py", line 660, in get_updates
    json_updates = apihelper.get_updates(
  File "/usr/local/lib/python3.10/dist-packages/telebot/apihelper.py", line 332, in get_updates
    return _make_request(token, method_url, params=payload)
  File "/usr/local/lib/python3.10/dist-packages/telebot/apihelper.py", line 162, in _make_request
    result = _get_req_session().request(
  File "/usr/lib/python3/dist-packages/requests/sessions.py", line 544, in request
    resp = self.send(prep, **send_kwargs)
  File "/usr/lib/python3/dist-packages/requests/sessions.py", line 657, in send
    r = adapter.send(request, **kwargs)
  File "/usr/lib/python3/dist-packages/requests/adapters.py", line 498, in send
    raise ConnectionError(err, request=request)
requests.exceptions.ConnectionError: ('Connection aborted.', RemoteDisconnected('Remote end closed connection without response'))
"
Бот запущен!

Получен сигнал завершения. Завершаем работу бота...
Бот завершил работу. Программа завершена.
Бот завершил работу.
./main.py: 1: import: not found
./main.py: 2: import: not found
./main.py: 3: from: not found
./main.py: 4: from: not found
./main.py: 5: from: not found
./main.py: 6: import: not found
./main.py: 7: import: not found
./main.py: 9: Syntax error: "(" unexpected
./main.py: 1: import: not found
./main.py: 2: import: not found
./main.py: 3: from: not found
./main.py: 4: from: not found
./main.py: 5: from: not found
./main.py: 6: import: not found
./main.py: 7: import: not found
./main.py: 9: Syntax error: "(" unexpected
2025-02-26 19:26:31,290 (__init__.py:1115 MainThread) ERROR - TeleBot: "Infinity polling exception: HTTPSConnectionPool(host='api.telegram.org', port=443): Read timed out. (read timeout=10)"
2025-02-26 19:26:31,294 (__init__.py:1117 MainThread) ERROR - TeleBot: "Exception traceback:
Traceback (most recent call last):
  File "/usr/lib/python3/dist-packages/urllib3/connectionpool.py", line 446, in _make_request
    six.raise_from(e, None)
  File "<string>", line 3, in raise_from
  File "/usr/lib/python3/dist-packages/urllib3/connectionpool.py", line 441, in _make_request
    httplib_response = conn.getresponse()
  File "/usr/lib/python3.10/http/client.py", line 1375, in getresponse
    response.begin()
  File "/usr/lib/python3.10/http/client.py", line 318, in begin
    version, status, reason = self._read_status()
  File "/usr/lib/python3.10/http/client.py", line 279, in _read_status
    line = str(self.fp.readline(_MAXLINE + 1), "iso-8859-1")
  File "/usr/lib/python3.10/socket.py", line 705, in readinto
    return self._sock.recv_into(b)
  File "/usr/lib/python3.10/ssl.py", line 1303, in recv_into
    return self.read(nbytes, buffer)
  File "/usr/lib/python3.10/ssl.py", line 1159, in read
    return self._sslobj.read(len, buffer)
TimeoutError: The read operation timed out

During handling of the above exception, another exception occurred:

Traceback (most recent call last):
  File "/usr/lib/python3/dist-packages/requests/adapters.py", line 439, in send
    resp = conn.urlopen(
  File "/usr/lib/python3/dist-packages/urllib3/connectionpool.py", line 756, in urlopen
    retries = retries.increment(
  File "/usr/lib/python3/dist-packages/urllib3/util/retry.py", line 534, in increment
    raise six.reraise(type(error), error, _stacktrace)
  File "/usr/lib/python3/dist-packages/six.py", line 719, in reraise
    raise value
  File "/usr/lib/python3/dist-packages/urllib3/connectionpool.py", line 700, in urlopen
    httplib_response = self._make_request(
  File "/usr/lib/python3/dist-packages/urllib3/connectionpool.py", line 448, in _make_request
    self._raise_timeout(err=e, url=url, timeout_value=read_timeout)
  File "/usr/lib/python3/dist-packages/urllib3/connectionpool.py", line 337, in _raise_timeout
    raise ReadTimeoutError(
urllib3.exceptions.ReadTimeoutError: HTTPSConnectionPool(host='api.telegram.org', port=443): Read timed out. (read timeout=10)

During handling of the above exception, another exception occurred:

Traceback (most recent call last):
  File "/usr/local/lib/python3.10/dist-packages/telebot/__init__.py", line 1110, in infinity_polling
    self.polling(non_stop=True, timeout=timeout, long_polling_timeout=long_polling_timeout,
  File "/usr/local/lib/python3.10/dist-packages/telebot/__init__.py", line 1198, in polling
    self.__threaded_polling(non_stop=non_stop, interval=interval, timeout=timeout, long_polling_timeout=long_polling_timeout,
  File "/usr/local/lib/python3.10/dist-packages/telebot/__init__.py", line 1273, in __threaded_polling
    raise e
  File "/usr/local/lib/python3.10/dist-packages/telebot/__init__.py", line 1234, in __threaded_polling
    polling_thread.raise_exceptions()
  File "/usr/local/lib/python3.10/dist-packages/telebot/util.py", line 111, in raise_exceptions
    raise self.exception_info
  File "/usr/local/lib/python3.10/dist-packages/telebot/util.py", line 93, in run
    task(*args, **kwargs)
  File "/usr/local/lib/python3.10/dist-packages/telebot/__init__.py", line 688, in __retrieve_updates
    updates = self.get_updates(offset=(self.last_update_id + 1),
  File "/usr/local/lib/python3.10/dist-packages/telebot/__init__.py", line 660, in get_updates
    json_updates = apihelper.get_updates(
  File "/usr/local/lib/python3.10/dist-packages/telebot/apihelper.py", line 332, in get_updates
    return _make_request(token, method_url, params=payload)
  File "/usr/local/lib/python3.10/dist-packages/telebot/apihelper.py", line 162, in _make_request
    result = _get_req_session().request(
  File "/usr/lib/python3/dist-packages/requests/sessions.py", line 544, in request
    resp = self.send(prep, **send_kwargs)
  File "/usr/lib/python3/dist-packages/requests/sessions.py", line 657, in send
    r = adapter.send(request, **kwargs)
  File "/usr/lib/python3/dist-packages/requests/adapters.py", line 529, in send
    raise ReadTimeout(e, request=request)
requests.exceptions.ReadTimeout: HTTPSConnectionPool(host='api.telegram.org', port=443): Read timed out. (read timeout=10)
"
2025-02-28 09:58:12,789 (__init__.py:1241 MainThread) ERROR - TeleBot: "Threaded polling exception: A request to the Telegram API was unsuccessful. Error code: 409. Description: Conflict: terminated by other getUpdates request; make sure that only one bot instance is running"
2025-02-28 09:58:12,791 (__init__.py:1243 MainThread) ERROR - TeleBot: "Exception traceback:
Traceback (most recent call last):
  File "/usr/local/lib/python3.10/dist-packages/telebot/__init__.py", line 1234, in __threaded_polling
    polling_thread.raise_exceptions()
  File "/usr/local/lib/python3.10/dist-packages/telebot/util.py", line 111, in raise_exceptions
    raise self.exception_info
  File "/usr/local/lib/python3.10/dist-packages/telebot/util.py", line 93, in run
    task(*args, **kwargs)
  File "/usr/local/lib/python3.10/dist-packages/telebot/__init__.py", line 688, in __retrieve_updates
    updates = self.get_updates(offset=(self.last_update_id + 1),
  File "/usr/local/lib/python3.10/dist-packages/telebot/__init__.py", line 660, in get_updates
    json_updates = apihelper.get_updates(
  File "/usr/local/lib/python3.10/dist-packages/telebot/apihelper.py", line 332, in get_updates
    return _make_request(token, method_url, params=payload)
  File "/usr/local/lib/python3.10/dist-packages/telebot/apihelper.py", line 168, in _make_request
    json_result = _check_result(method_name, result)
  File "/usr/local/lib/python3.10/dist-packages/telebot/apihelper.py", line 195, in _check_result
    raise ApiTelegramException(method_name, result, result_json)
telebot.apihelper.ApiTelegramException: A request to the Telegram API was unsuccessful. Error code: 409. Description: Conflict: terminated by other getUpdates request; make sure that only one bot instance is running
"
2025-02-28 09:58:16,466 (__init__.py:1241 MainThread) ERROR - TeleBot: "Threaded polling exception: A request to the Telegram API was unsuccessful. Error code: 409. Description: Conflict: terminated by other getUpdates request; make sure that only one bot instance is running"
2025-02-28 09:58:16,467 (__init__.py:1243 MainThread) ERROR - TeleBot: "Exception traceback:
Traceback (most recent call last):
  File "/usr/local/lib/python3.10/dist-packages/telebot/__init__.py", line 1234, in __threaded_polling
    polling_thread.raise_exceptions()
  File "/usr/local/lib/python3.10/dist-packages/telebot/util.py", line 111, in raise_exceptions
    raise self.exception_info
  File "/usr/local/lib/python3.10/dist-packages/telebot/util.py", line 93, in run
    task(*args, **kwargs)
  File "/usr/local/lib/python3.10/dist-packages/telebot/__init__.py", line 688, in __retrieve_updates
    updates = self.get_updates(offset=(self.last_update_id + 1),
  File "/usr/local/lib/python3.10/dist-packages/telebot/__init__.py", line 660, in get_updates
    json_updates = apihelper.get_updates(
  File "/usr/local/lib/python3.10/dist-packages/telebot/apihelper.py", line 332, in get_updates
    return _make_request(token, method_url, params=payload)
  File "/usr/local/lib/python3.10/dist-packages/telebot/apihelper.py", line 168, in _make_request
    json_result = _check_result(method_name, result)
  File "/usr/local/lib/python3.10/dist-packages/telebot/apihelper.py", line 195, in _check_result
    raise ApiTelegramException(method_name, result, result_json)
telebot.apihelper.ApiTelegramException: A request to the Telegram API was unsuccessful. Error code: 409. Description: Conflict: terminated by other getUpdates request; make sure that only one bot instance is running
"
2025-02-28 09:58:20,631 (__init__.py:1241 MainThread) ERROR - TeleBot: "Threaded polling exception: A request to the Telegram API was unsuccessful. Error code: 409. Description: Conflict: terminated by other getUpdates request; make sure that only one bot instance is running"
2025-02-28 09:58:20,631 (__init__.py:1243 MainThread) ERROR - TeleBot: "Exception traceback:
Traceback (most recent call last):
  File "/usr/local/lib/python3.10/dist-packages/telebot/__init__.py", line 1234, in __threaded_polling
    polling_thread.raise_exceptions()
  File "/usr/local/lib/python3.10/dist-packages/telebot/util.py", line 111, in raise_exceptions
    raise self.exception_info
  File "/usr/local/lib/python3.10/dist-packages/telebot/util.py", line 93, in run
    task(*args, **kwargs)
  File "/usr/local/lib/python3.10/dist-packages/telebot/__init__.py", line 688, in __retrieve_updates
    updates = self.get_updates(offset=(self.last_update_id + 1),
  File "/usr/local/lib/python3.10/dist-packages/telebot/__init__.py", line 660, in get_updates
    json_updates = apihelper.get_updates(
  File "/usr/local/lib/python3.10/dist-packages/telebot/apihelper.py", line 332, in get_updates
    return _make_request(token, method_url, params=payload)
  File "/usr/local/lib/python3.10/dist-packages/telebot/apihelper.py", line 168, in _make_request
    json_result = _check_result(method_name, result)
  File "/usr/local/lib/python3.10/dist-packages/telebot/apihelper.py", line 195, in _check_result
    raise ApiTelegramException(method_name, result, result_json)
telebot.apihelper.ApiTelegramException: A request to the Telegram API was unsuccessful. Error code: 409. Description: Conflict: terminated by other getUpdates request; make sure that only one bot instance is running
"
Бот запущен!

Получен сигнал завершения. Завершаем работу бота...
Бот завершил работу. Программа завершена.
Бот завершил работу.
